Workbook

Sheet 预安排
A1: 代码 | B1: 批发价 | C1: 卷烟名称 | D1: 类 | E1: 合计 | F1: 需求 | G1: 可用 货源 | H1: 属 | I1: C类 | J1: 品牌 | K1: 条支比 | L1: C | M1: 按需 | N1: 按价 | O1: 第一轮 | P1: 第二轮 | Q1: 第三轮 | R1: 第四轮 | S1: 第五轮
A2: SKU-C78CA26A | B2: 100 | C2: Product-0CBDA773 | D2: 3 | E2: 1079.784 | F2: 333.1 | G2: 137.228 | J2: Brand-Anonymized | K2: 200 | O2: 0 | P2: 85 | Q2: 85 | R2: 85 | S2: 78.1
A3: SKU-FEFFF06B | B3: 100 | C3: Product-2824E2BD | D3: 2 | E3: 15.59 | F3: 28.1 | G3: 1.14 | H3: T | J3: Brand-Anonymized | K3: 200 | O3: 0 | P3: 28.1 | Q3: 0 | R3: 0 | S3: 0
A4: SKU-2866FD1A | B4: 100 | C4: Product-B05D24B5 | D4: 3 | E4: 138.016 | F4: 39.8 | G4: 16.272 | J4: Brand-Anonymized | K4: 200 | O4: 0 | P4: 0 | Q4: 39.8 | R4: 0 | S4: 0
A5: SKU-0260B714 | B5: 100 | C5: Product-9FA41960 | D5: 2 | E5: 0 | F5: 0 | G5: 0 | J5: Brand-Anonymized | K5: 200 | O5: 0 | P5: 0 | Q5: 0 | R5: 0 | S5: 0
A6: SKU-80DD304E | B6: 100 | C6: Product-104B7147 | D6: 2 | E6: 26.026 | F6: 10 | G6: 10.372 | H6: C | I6: 标 | J6: Brand-Anonymized | K6: 200 | L6: C | O6: 10 | P6: 0 | Q6: 0 | R6: 0 | S6: 0
A7: SKU-1DE29866 | B7: 100 | C7: Product-F23B59C1 | D7: 1 | E7: 153.11 | F7: 70 | G7: 4.9 | H7: X | I7: 标 | J7: Brand-Anonymized | K7: 200 | L7: C | O7: 0 | P7: 35 | Q7: 0 | R7: 35 | S7: 0
A8: SKU-99A87208 | B8: 100 | C8: Product-658841C6 | D8: 1 | F8: 15 | G8: 5 | H8: X | I8: 细 | J8: Brand-Anonymized | K8: 200 | L8: C | O8: 0 | P8: 7.5 | Q8: 0 | R8: 7.5 | S8: 0
A9: SKU-D208A1F4 | B9: 100 | C9: Product-DE70A72E | D9: 3 | E9: 2475.25 | F9: 1035.3 | G9: 243.76 | H9: T | J9: Brand-Anonymized | K9: 200 | O9: 200 | P9: 222 | Q9: 223 | R9: 235 | S9: 155.3
A10: SKU-07FCDFBC | B10: 100 | C10: Product-7A1FEE2B | D10: 1 | E10: 0 | F10: 0 | G10: 0 | I10: 标 | J10: Brand-Anonymized | K10: 200 | L10: C | O10: 0 | P10: 0 | Q10: 0 | R10: 0 | S10: 0
A11: SKU-F24DC4CC | B11: 100 | C11: Product-3F617BC6 | D11: 1 | E11: -43.42 | F11: 0 | G11: 0 | I11: 方 | J11: Brand-Anonymized | K11: 200 | L11: C | O11: 0 | P11: 0 | Q11: 0 | R11: 0 | S11: 0
A12: SKU-D943D84F | B12: 100 | C12: Product-9C089579 | D12: 1 | E12: 0 | F12: 0 | G12: 0 | J12: Brand-Anonymized | K12: 200 | O12: 0 | P12: 0 | Q12: 0 | R12: 0 | S12: 0
A13: SKU-6D9E63BD | B13: 100 | C13: Product-BC499EF2 | D13: 1 | E13: 54.688 | F13: 60 | G13: 6.296 | H13: C | I13: 方 | J13: Brand-Anonymized | K13: 200 | L13: C | O13: 0 | P13: 0 | Q13: 60 | R13: 0 | S13: 0
A14: SKU-01FF2431 | B14: 100 | C14: Product-C54A353F | D14: 1 | E14: 369.198 | F14: 140 | G14: 51.476 | H14: C | I14: 标 | J14: Brand-Anonymized | K14: 200 | L14: C | O14: 50 | P14: 0 | Q14: 50 | R14: 0 | S14: 40
A15: SKU-8916FAEC | B15: 100 | C15: Product-558A622A | D15: 1 | E15: 688.626 | F15: 302.78 | G15: 151.132 | H15: C | I15: 长 | J15: Brand-Anonymized | K15: 200 | L15: C | O15: 150 | P15: 152.78 | Q15: 0 | R15: 0 | S15: 0
A16: SKU-13F48E9F | B16: 100 | C16: Product-9B1626A5 | D16: 1 | E16: 182.012 | F16: 80 | G16: 20.184 | H16: C | I16: 长 | J16: Brand-Anonymized | K16: 200 | L16: C | O16: 20 | P16: 20 | Q16: 20 | R16: 20 | S16: 0
A17: SKU-3095C758 | B17: 100 | C17: Product-280802D6 | D17: 4 | E17: 4873.926 | F17: 1360.8 | G17: 897.592 | H17: T | J17: Brand-Anonymized | K17: 200 | O17: 300 | P17: 300 | Q17: 300 | R17: 300 | S17: 160.8
A18: SKU-22512FF3 | B18: 100 | C18: Product-C617F7D2 | D18: 1 | E18: 1937.902 | F18: 700 | G18: 247.884 | H18: C | J18: Brand-Anonymized | K18: 200 | O18: 140 | P18: 140 | Q18: 140 | R18: 140 | S18: 140
A19: SKU-8B1D5EF6 | B19: 100 | C19: Product-C0E4574A | D19: 1 | E19: 240.72 | F19: 50 | G19: 50 | H19: C | I19: 标 | J19: Brand-Anonymized | K19: 200 | L19: C | O19: 0 | P19: 25 | Q19: 0 | R19: 25 | S19: 0
A20: SKU-8BA825B6 | B20: 100 | C20: Product-E7EC78F7 | D20: 1 | E20: 196.492 | F20: 70 | G20: 22.424 | H20: C | I20: 标 | J20: Brand-Anonymized | K20: 200 | L20: C | O20: 0 | P20: 35 | Q20: 0 | R20: 35 | S20: 0
A21: SKU-DBE8D847 | B21: 100 | C21: Product-31FC13CA | D21: 2 | E21: 404.022 | F21: 71.8 | G21: 75.684 | I21: 细 | J21: Brand-Anonymized | K21: 200 | L21: C | O21: 0 | P21: 0 | Q21: 71.8 | R21: 0 | S21: 0
A22: SKU-993415A4 | B22: 100 | C22: Product-914BA5F4 | D22: 3 | E22: 158.204 | F22: 52.3 | G22: 7.868 | J22: Brand-Anonymized | K22: 200 | O22: 0 | P22: 0 | Q22: 0 | R22: 52.3 | S22: 0
A23: SKU-D86E9747 | B23: 100 | C23: Product-FF4227EA | D23: 1 | E23: 0 | F23: 0 | G23: 0 | J23: Brand-Anonymized | K23: 200 | O23: 0 | P23: 0 | Q23: 0 | R23: 0 | S23: 0
A24: SKU-7CB9F294 | B24: 100 | C24: Product-1F3A5A4E | D24: 1 | E24: 77.364 | F24: 5 | G24: 5.628 | H24: X | J24: Brand-Anonymized | K24: 200 | O24: 2 | P24: 0 | Q24: 3 | R24: 0 | S24: 0
A25: SKU-6FADBEBD | B25: 100 | C25: Product-224E6368 | D25: 1 | E25: -51.756 | F25: 6.776 | G25: 0.156 | I25: 细 | J25: Brand-Anonymized | K25: 200 | L25: C | O25: 0 | P25: 6.776 | Q25: 0 | R25: 0 | S25: 0
A26: SKU-6772DEBE | B26: 100 | C26: Product-82693D22 | D26: 1 | E26: 278.702 | F26: 94.3 | G26: 44.344 | I26: 长 | J26: Brand-Anonymized | K26: 200 | L26: C | O26: 0 | P26: 47 | Q26: 47.3 | R26: 0 | S26: 0
A27: SKU-3B2628FE | B27: 100 | C27: Product-F68D7468 | D27: 1 | E27: 0 | F27: 0 | G27: 0 | J27: Brand-Anonymized | K27: 200 | O27: 0 | P27: 0 | Q27: 0 | R27: 0 | S27: 0
A28: SKU-01CFC7C8 | B28: 100 | C28: Product-1385CA82 | D28: 1 | E28: -11.098 | F28: 5 | G28: 5.284 | H28: X | I28: 细 | J28: Brand-Anonymized | K28: 200 | L28: C | O28: 0 | P28: 5 | Q28: 0 | R28: 0 | S28: 0
A29: SKU-3BC6D3D6 | B29: 100 | C29: Product-7FD02DE1 | D29: 2 | E29: 377.596 | F29: 140.7 | G29: 65.812 | J29: Brand-Anonymized | K29: 200 | O29: 45 | P29: 45 | Q29: 0 | R29: 50.7 | S29: 0
A30: SKU-4BF6BE09 | B30: 100 | C30: Product-685982B2 | D30: 2 | E30: 0 | F30: 0 | G30: 0 | J30: Brand-Anonymized | K30: 200 | O30: 0 | P30: 0 | Q30: 0 | R30: 0 | S30: 0
A31: SKU-68F01DAC | B31: 100 | C31: Product-DB12469B | D31: 2 | E31: 998.866 | F31: 213.5 | G31: 214.852 | I31: 细 | J31: Brand-Anonymized | K31: 200 | L31: C | O31: 71 | P31: 0 | Q31: 71 | R31: 71.5 | S31: 0
A32: SKU-B376DBC8 | B32: 100 | C32: Product-12486764 | D32: 1 | E32: 0 | F32: 0 | G32: 0 | I32: 方 | J32: Brand-Anonymized | K32: 200 | L32: C | O32: 0 | P32: 0 | Q32: 0 | R32: 0 | S32: 0
A33: SKU-D051F69D | B33: 100 | C33: Product-89AAAC0F | D33: 1 | E33: -9.696 | F33: 15 | G33: 15.268 | H33: X | I33: 标 | J33: Brand-Anonymized | K33: 200 | L33: C | O33: 15 | P33: 0 | Q33: 0 | R33: 0 | S33: 0
A34: SKU-D6DABD2C | B34: 100 | C34: Product-E13E7723 | D34: 1 | E34: 77.854 | F34: 24 | G34: 24.028 | H34: X | I34: 细 | J34: Brand-Anonymized | K34: 200 | L34: C | O34: 0 | P34: 12 | Q34: 0 | R34: 12 | S34: 0
A35: SKU-58C29290 | B35: 100 | C35: Product-0F81BD89 | D35: 3 | E35: 1391.158 | F35: 503 | G35: 211.296 | J35: Brand-Anonymized | K35: 200 | O35: 130 | P35: 130 | Q35: 130 | R35: 113 | S35: 0
A36: SKU-204217AA | B36: 100 | C36: Product-65B192F5 | D36: 3 | E36: 2203.414 | F36: 680.5 | G36: 351.148 | H36: T | J36: Brand-Anonymized | K36: 200 | O36: 130 | P36: 150 | Q36: 130 | R36: 140 | S36: 130.5
A37: SKU-AA06D68B | B37: 100 | C37: Product-BC490182 | D37: 1 | E37: 78.274 | F37: 29.7 | G37: 12.068 | J37: Brand-Anonymized | K37: 200 | O37: 0 | P37: 0 | Q37: 29.7 | R37: 0 | S37: 0
A38: SKU-AB711576 | B38: 100 | C38: Product-606B1B6A | D38: 2 | E38: 3952.988 | F38: 1404.4 | G38: 563.816 | H38: T | I38: 细 | J38: Brand-Anonymized | K38: 200 | L38: C | O38: 300 | P38: 320 | Q38: 320 | R38: 280 | S38: 184.4
A39: SKU-9F810407 | B39: 100 | C39: Product-F93B8445 | D39: 3 | E39: 1246.84 | F39: 444.2 | G39: 180.72 | I39: 细 | J39: Brand-Anonymized | K39: 200 | L39: C | O39: 112 | P39: 112 | Q39: 112 | R39: 108.2 | S39: 0
A40: SKU-F676B681 | B40: 100 | C40: Product-33875634 | D40: 1 | E40: 0 | F40: 0 | G40: 0 | J40: Brand-Anonymized | K40: 200 | O40: 0 | P40: 0 | Q40: 0 | R40: 0 | S40: 0
...

Sheet Sheet1
B1: 销量 | C1: 单箱
A2: 第一轮 | B2: 10000.488 | C2: 38343.3
A3: 第二轮 | B3: 12302.076 | C3: 36866.165
A4: 第三轮 | B4: 12000.264 | C4: 36876.673
A5: 第四轮 | B5: 12099.084 | C5: 36193.911
A6: 第五轮 | B6: 5976.232 | C6: 33985.664

Sheet 6月
M1: 2025年上
A2: 工业 | B2: 代码 | C2: 重 | D2: 焦 | E2: 细 | F2: 中 | G2: 短 | H2: 爆 | I2: 创 | J2: 共 | K2: 混 | L2: 批发价 | M2: 卷烟名称 | N2: 类 | O2: 合计 | P2: 一分 | Q2: 二分 | R2: 三分 | S2: 东丽 | T2: 西青 | U2: 津南 | V2: 北辰 | W2: 滨海 | X2: 武清 | Y2: 宝坻 | Z2: 蓟州 | AA2: 静海 | AB2: 宁河 | AC2: 属 | AD2: C类 | AE2: 品牌 | AF2: 条支比 | AG2: C
A3: 上海 | B3: SKU-C78CA26A | C3: 是 | D3: 8 | K3: 是 | L3: 100 | M3: Product-0CBDA773 | N3: 3 | O3: =SUM(P3:AB3) | AE3: Brand-Anonymized | AF3: 200
B4: SKU-FEFFF06B | C4: 是 | D4: 5 | K4: 是 | L4: 100 | M4: Product-2824E2BD | N4: 2 | O4: =SUM(P4:AB4) | AC4: T | AE4: Brand-Anonymized | AF4: 200
B5: SKU-2866FD1A | C5: 是 | D5: 8 | K5: 是 | L5: 100 | M5: Product-B05D24B5 | N5: 3 | O5: =SUM(P5:AB5) | AE5: Brand-Anonymized | AF5: 200
B6: SKU-0260B714 | C6: 是 | D6: 5 | K6: 是 | L6: 100 | M6: Product-9FA41960 | N6: 2 | O6: =SUM(P6:AB6) | AE6: Brand-Anonymized | AF6: 200
B7: SKU-80DD304E | C7: 是 | D7: 5 | F7: 是 | I7: 是 | K7: 是 | L7: 100 | M7: Product-104B7147 | N7: 2 | O7: =SUM(P7:AB7) | AC7: C | AD7: 标 | AE7: Brand-Anonymized | AF7: 200 | AG7: C
B8: SKU-1DE29866 | C8: 是 | D8: 5 | F8: 是 | H8: 是 | I8: 是 | K8: 是 | L8: 100 | M8: Product-F23B59C1 | N8: 1 | O8: =SUM(P8:AB8) | AC8: X | AD8: 标 | AE8: Brand-Anonymized | AF8: 200 | AG8: C
M9: 北京小计 | O9: =SUM(O3:O8) | P9: =SUM(P3:P8) | Q9: =SUM(Q3:Q8) | R9: =SUM(R3:R8) | S9: =SUM(S3:S8) | T9: =SUM(T3:T8) | U9: =SUM(U3:U8) | V9: =SUM(V3:V8) | ... AC9: =SUM(AC3:AC8)
B10: SKU-D208A1F4 | D10: 9 | L10: 100 | M10: Product-DE70A72E | N10: 3 | O10: =SUM(P10:AB10) | AC10: T | AE10: Brand-Anonymized | AF10: 200
B11: SKU-07FCDFBC | D11: 10 | G11: 是 | I11: 是 | L11: 100 | M11: Product-7A1FEE2B | N11: 1 | O11: =SUM(P11:AB11) | AD11: 标 | AE11: Brand-Anonymized | AF11: 200 | AG11: C
B12: SKU-F24DC4CC | D12: 10 | L12: 100 | M12: Product-3F617BC6 | N12: 1 | O12: =SUM(P12:AB12) | AD12: 方 | AE12: Brand-Anonymized | AF12: 200 | AG12: C
B13: SKU-D943D84F | D13: 10 | L13: 100 | M13: Product-9C089579 | N13: 1 | O13: =SUM(P13:AB13) | AE13: Brand-Anonymized | AF13: 200
B14: SKU-6D9E63BD | D14: 8 | F14: 是 | I14: 是 | L14: 100 | M14: Product-BC499EF2 | N14: 1 | O14: =SUM(P14:AB14) | AC14: C | AD14: 方 | AE14: Brand-Anonymized | AF14: 200 | AG14: C
B15: SKU-01FF2431 | D15: 8 | F15: 是 | I15: 是 | L15: 100 | M15: Product-C54A353F | N15: 1 | O15: =SUM(P15:AB15) | AC15: C | AD15: 标 | AE15: Brand-Anonymized | AF15: 200 | AG15: C
B16: SKU-8916FAEC | D16: 8 | F16: 是 | I16: 是 | J16: 共 | L16: 100 | M16: Product-558A622A | N16: 1 | O16: =SUM(P16:AB16) | AC16: C | AD16: 长 | AE16: Brand-Anonymized | AF16: 200 | AG16: C
B17: SKU-13F48E9F | D17: 8 | F17: 是 | I17: 是 | L17: 100 | M17: Product-9B1626A5 | N17: 1 | O17: =SUM(P17:AB17) | AC17: C | AD17: 长 | AE17: Brand-Anonymized | AF17: 200 | AG17: C
B18: SKU-84735B62 | C18: 是 | D18: 10 | L18: 100 | M18: Product-61AE19F7 | N18: 3 | O18: =SUM(P18:AB18) | AC18: T | AE18: Brand-Anonymized | AF18: 200
B19: SKU-9356910A | C19: 是 | D19: 11 | L19: 100 | M19: Product-1433AC24 | N19: 2 | O19: =SUM(P19:AB19) | AC19: T | AE19: Brand-Anonymized | AF19: 200
B20: SKU-A1C9F3C5 | C20: 是 | D20: 10 | J20: 共 | L20: 100 | M20: Product-A7F669A5 | N20: 2 | O20: =SUM(P20:AB20) | AC20: T | AE20: Brand-Anonymized | AF20: 200
B21: SKU-9FED3CD7 | C21: 是 | D21: 6 | E21: 是 | I21: 是 | L21: 100 | M21: Product-80F515FA | N21: 1 | O21: =SUM(P21:AB21) | AD21: 方 | AE21: Brand-Anonymized | AF21: 200 | AG21: C
B22: SKU-D2D4FD85 | C22: 是 | D22: 8 | E22: 是 | I22: 是 | L22: 100 | M22: Product-D1D130D9 | N22: 1 | O22: =SUM(P22:AB22) | AE22: Brand-Anonymized | AF22: 200
B23: SKU-2324D87D | C23: 是 | D23: 9 | F23: 是 | I23: 是 | L23: 100 | M23: Product-142947AA | N23: 1 | O23: =SUM(P23:AB23) | AC23: C | AD23: 长 | AE23: Brand-Anonymized | AF23: 200 | AG23: C
B24: SKU-D3A8D0D1 | C24: 是 | D24: 9 | F24: 是 | I24: 是 | L24: 100 | M24: Product-B80128BB | N24: 1 | O24: =SUM(P24:AB24) | AC24: X | AD24: 长 | AE24: Brand-Anonymized | AF24: 200 | AG24: C
B25: SKU-55B49425 | C25: 是 | D25: 11 | J25: 共 | L25: 100 | M25: Product-2E005B6F | N25: 1 | O25: =SUM(P25:AB25) | AC25: T | AE25: Brand-Anonymized | AF25: 200
B26: SKU-7E7C0C23 | C26: 是 | D26: 11 | J26: 共 | L26: 100 | M26: Product-8C5BA899 | N26: 1 | O26: =SUM(P26:AB26) | AC26: T | AE26: Brand-Anonymized | AF26: 200
B27: SKU-581048FF | C27: 是 | D27: 11 | L27: 100 | M27: Product-9C9F0DD0 | N27: 1 | O27: =SUM(P27:AB27) | AC27: C | AD27: 方 | AE27: Brand-Anonymized | AF27: 200 | AG27: C
B28: SKU-1943C75B | C28: 是 | D28: 10 | F28: 是 | I28: 是 | J28: 共 | L28: 100 | M28: Product-62BC29B7 | N28: 1 | O28: =SUM(P28:AB28) | AC28: C | AD28: 方 | AE28: Brand-Anonymized | AF28: 200 | AG28: C
B29: SKU-51C641E5 | C29: 是 | D29: 10 | F29: 是 | I29: 是 | J29: 共 | L29: 100 | M29: Product-4CA63C06 | N29: 1 | O29: =SUM(P29:AB29) | AC29: T | AD29: 长 | AE29: Brand-Anonymized | AF29: 200 | AG29: C
B30: SKU-740A9334 | C30: 是 | D30: 10 | G30: 是 | I30: 是 | L30: 100 | M30: Product-7726A962 | N30: 1 | O30: =SUM(P30:AB30) | AD30: 方 | AE30: Brand-Anonymized | AF30: 200 | AG30: C
B31: SKU-ABAD8823 | C31: 是 | D31: 8 | E31: 是 | I31: 是 | J31: 共 | L31: 100 | M31: Product-342D1F0D | N31: 1 | O31: =SUM(P31:AB31) | AC31: C | AD31: 细 | AE31: Brand-Anonymized | AF31: 200 | AG31: C
B32: SKU-CD40403A | C32: 是 | D32: 8 | E32: 是 | I32: 是 | J32: 共 | L32: 100 | M32: Product-D6D3CCE6 | N32: 1 | O32: =SUM(P32:AB32) | AC32: C | AD32: 标 | AE32: Brand-Anonymized | AF32: 200 | AG32: C
B33: SKU-B0D292B1 | C33: 是 | D33: 10 | G33: 是 | I33: 是 | L33: 100 | M33: Product-7726A962 | N33: 1 | O33: =SUM(P33:AB33) | AC33: X | AD33: 标 | AE33: Brand-Anonymized | AF33: 200 | AG33: C
B34: SKU-D5FB4C4D | D34: 10 | L34: 100 | M34: Product-3DCEC0C0 | N34: 1 | O34: =SUM(P34:AB34) | AD34: 标 | AE34: Brand-Anonymized | AF34: 200 | AG34: C
B35: SKU-DCF98B33 | D35: 10 | L35: 100 | M35: Product-3DCEC0C0 | N35: 1 | O35: =SUM(P35:AB35) | AC35: X | AD35: 标 | AE35: Brand-Anonymized | AF35: 200 | AG35: C
B36: SKU-7ECD2FA6 | D36: 10 | F36: 是 | I36: 是 | L36: 100 | M36: Product-29355C79 | N36: 1 | O36: =SUM(P36:AB36) | AC36: X | AE36: Brand-Anonymized | AF36: 200
M37: 津沪小计 | O37: =SUM(O10:O36) | P37: =SUM(P10:P36) | Q37: =SUM(Q10:Q36) | R37: =SUM(R10:R36) | S37: =SUM(S10:S36) | T37: =SUM(T10:T36) | U37: =SUM(U10:U36) | V37: =SUM(V10:V36) | ... AC37: =SUM(AC10:AC36)
M38: 上海小计 | O38: =O9+O37 | P38: =P9+P37 | Q38: =Q9+Q37 | R38: =R9+R37 | S38: =S9+S37 | T38: =T9+T37 | U38: =U9+U37 | V38: =V9+V37 | ... AC38: =AC9+AC37
A39: 河北 | B39: SKU-3095C758 | C39: 是 | D39: 11 | L39: 100 | M39: Product-280802D6 | N39: 4 | O39: =SUM(P39:AB39) | AC39: T | AE39: Brand-Anonymized | AF39: 200
B40: SKU-22512FF3 | C40: 是 | D40: 10 | J40: 共 | L40: 100 | M40: Product-C617F7D2 | N40: 1 | O40: =SUM(P40:AB40) | AC40: C | AE40: Brand-Anonymized | AF40: 200
...

Sheet 计划落实
M1: 2025年上 | AH1: 20
A2: 工业 | B2: 代码 | C2: 重 | D2: 焦 | E2: 细 | F2: 中 | G2: 短 | H2: 爆 | I2: 创 | J2: 共 | K2: 混 | L2: 批发价 | M2: 卷烟名称 | N2: 类 | O2: 合计 | P2: 一分 | Q2: 二分 | R2: 三分 | S2: 东丽 | T2: 西青 | U2: 津南 | V2: 北辰 | W2: 滨海 | X2: 武清 | Y2: 宝坻 | Z2: 蓟州 | AA2: 静海 | AB2: 宁河 | AC2: 属 | AD2: C类 | AE2: 品牌 | AF2: 条支比 | AG2: 计划剩余 | AH2: 剩余轮均
A3: 上海 | B3: SKU-C78CA26A | C3: 是 | D3: 8 | K3: 是 | L3: 100 | M3: Product-0CBDA773 | N3: 3 | O3: =SUM(P3:AB3) | P3: =ROUND(#REF!+#REF!+#REF!+预安排!F2+#REF!+'6月'!P3,5) | Q3: =ROUND(#REF!+#REF!+#REF!+预安排!#REF!+#REF!+'6月'!Q3,5) | R3: =ROUND(#REF!+#REF!+#REF!+预安排!G2+#REF!+'6月'!R3,5) | S3: =ROUND(#REF!+#REF!+#REF!+预安排!#REF!+#REF!+'6月'!S3,5) | T3: =ROUND(#REF!+#REF!+#REF!+预安排!#REF!+#REF!+'6月'!T3,5) | U3: =ROUND(#REF!+#REF!+#REF!+预安排!O2+#REF!+'6月'!U3,5) | V3: =ROUND(#REF!+#REF!+#REF!+预安排!P2+#REF!+'6月'!V3,5) | W3: =ROUND(#REF!+#REF!+#REF!+预安排!Q2+#REF!+'6月'!W3,5) | X3: =ROUND(#REF!+#REF!+#REF!+预安排!R2+#REF!+'6月'!X3,5) | Y3: =ROUND(#REF!+#REF!+#REF!+预安排!S2+#REF!+'6月'!Y3,5) | Z3: =ROUND(#REF!+#REF!+#REF!+预安排!#REF!+#REF!+'6月'!Z3,5) | AA3: =ROUND(#REF!+#REF!+#REF!+预安排!#REF!+#REF!+'6月'!AA3,5) | AB3: =ROUND(#REF!+#REF!+#REF!+预安排!#REF!+#REF!+'6月'!AB3,5) | AE3: Brand-Anonymized | AF3: 200 | AG3: =计划!O3-O3 | AH3: =ROUND(AG3/$AH$1,2)
B4: SKU-FEFFF06B | C4: 是 | D4: 5 | K4: 是 | L4: 100 | M4: Product-2824E2BD | N4: 2 | O4: =SUM(P4:AB4) | P4: =ROUND(#REF!+#REF!+#REF!+预安排!F3+#REF!+'6月'!P4,5) | Q4: =ROUND(#REF!+#REF!+#REF!+预安排!#REF!+#REF!+'6月'!Q4,5) | R4: =ROUND(#REF!+#REF!+#REF!+预安排!G3+#REF!+'6月'!R4,5) | S4: =ROUND(#REF!+#REF!+#REF!+预安排!#REF!+#REF!+'6月'!S4,5) | T4: =ROUND(#REF!+#REF!+#REF!+预安排!#REF!+#REF!+'6月'!T4,5) | U4: =ROUND(#REF!+#REF!+#REF!+预安排!O3+#REF!+'6月'!U4,5) | V4: =ROUND(#REF!+#REF!+#REF!+预安排!P3+#REF!+'6月'!V4,5) | W4: =ROUND(#REF!+#REF!+#REF!+预安排!Q3+#REF!+'6月'!W4,5) | X4: =ROUND(#REF!+#REF!+#REF!+预安排!R3+#REF!+'6月'!X4,5) | Y4: =ROUND(#REF!+#REF!+#REF!+预安排!S3+#REF!+'6月'!Y4,5) | Z4: =ROUND(#REF!+#REF!+#REF!+预安排!#REF!+#REF!+'6月'!Z4,5) | AA4: =ROUND(#REF!+#REF!+#REF!+预安排!#REF!+#REF!+'6月'!AA4,5) | AB4: =ROUND(#REF!+#REF!+#REF!+预安排!#REF!+#REF!+'6月'!AB4,5) | AC4: T | AE4: Brand-Anonymized | AF4: 200 | AG4: =计划!O4-O4 | AH4: =ROUND(AG4/$AH$1,2)
B5: SKU-2866FD1A | C5: 是 | D5: 8 | K5: 是 | L5: 100 | M5: Product-B05D24B5 | N5: 3 | O5: =SUM(P5:AB5) | P5: =ROUND(#REF!+#REF!+#REF!+预安排!F4+#REF!+'6月'!P5,5) | Q5: =ROUND(#REF!+#REF!+#REF!+预安排!#REF!+#REF!+'6月'!Q5,5) | R5: =ROUND(#REF!+#REF!+#REF!+预安排!G4+#REF!+'6月'!R5,5) | S5: =ROUND(#REF!+#REF!+#REF!+预安排!#REF!+#REF!+'6月'!S5,5) | T5: =ROUND(#REF!+#REF!+#REF!+预安排!#REF!+#REF!+'6月'!T5,5) | U5: =ROUND(#REF!+#REF!+#REF!+预安排!O4+#REF!+'6月'!U5,5) | V5: =ROUND(#REF!+#REF!+#REF!+预安排!P4+#REF!+'6月'!V5,5) | W5: =ROUND(#REF!+#REF!+#REF!+预安排!Q4+#REF!+'6月'!W5,5) | X5: =ROUND(#REF!+#REF!+#REF!+预安排!R4+#REF!+'6月'!X5,5) | Y5: =ROUND(#REF!+#REF!+#REF!+预安排!S4+#REF!+'6月'!Y5,5) | Z5: =ROUND(#REF!+#REF!+#REF!+预安排!#REF!+#REF!+'6月'!Z5,5) | AA5: =ROUND(#REF!+#REF!+#REF!+预安排!#REF!+#REF!+'6月'!AA5,5) | AB5: =ROUND(#REF!+#REF!+#REF!+预安排!#REF!+#REF!+'6月'!AB5,5) | AE5: Brand-Anonymized | AF5: 200 | AG5: =计划!O5-O5 | AH5: =ROUND(AG5/$AH$1,2)
B6: SKU-0260B714 | C6: 是 | D6: 5 | K6: 是 | L6: 100 | M6: Product-9FA41960 | N6: 2 | O6: =SUM(P6:AB6) | P6: =ROUND(#REF!+#REF!+#REF!+预安排!F5+#REF!+'6月'!P6,5) | Q6: =ROUND(#REF!+#REF!+#REF!+预安排!#REF!+#REF!+'6月'!Q6,5) | R6: =ROUND(#REF!+#REF!+#REF!+预安排!G5+#REF!+'6月'!R6,5) | S6: =ROUND(#REF!+#REF!+#REF!+预安排!#REF!+#REF!+'6月'!S6,5) | T6: =ROUND(#REF!+#REF!+#REF!+预安排!#REF!+#REF!+'6月'!T6,5) | U6: =ROUND(#REF!+#REF!+#REF!+预安排!O5+#REF!+'6月'!U6,5) | V6: =ROUND(#REF!+#REF!+#REF!+预安排!P5+#REF!+'6月'!V6,5) | W6: =ROUND(#REF!+#REF!+#REF!+预安排!Q5+#REF!+'6月'!W6,5) | X6: =ROUND(#REF!+#REF!+#REF!+预安排!R5+#REF!+'6月'!X6,5) | Y6: =ROUND(#REF!+#REF!+#REF!+预安排!S5+#REF!+'6月'!Y6,5) | Z6: =ROUND(#REF!+#REF!+#REF!+预安排!#REF!+#REF!+'6月'!Z6,5) | AA6: =ROUND(#REF!+#REF!+#REF!+预安排!#REF!+#REF!+'6月'!AA6,5) | AB6: =ROUND(#REF!+#REF!+#REF!+预安排!#REF!+#REF!+'6月'!AB6,5) | AE6: Brand-Anonymized | AF6: 200 | AG6: =计划!O6-O6 | AH6: =ROUND(AG6/$AH$1,2)
B7: SKU-80DD304E | C7: 是 | D7: 5 | F7: 是 | I7: 是 | K7: 是 | L7: 100 | M7: Product-104B7147 | N7: 2 | O7: =SUM(P7:AB7) | P7: =ROUND(#REF!+#REF!+#REF!+预安排!F6+#REF!+'6月'!P7,5) | Q7: =ROUND(#REF!+#REF!+#REF!+预安排!#REF!+#REF!+'6月'!Q7,5) | R7: =ROUND(#REF!+#REF!+#REF!+预安排!G6+#REF!+'6月'!R7,5) | S7: =ROUND(#REF!+#REF!+#REF!+预安排!#REF!+#REF!+'6月'!S7,5) | T7: =ROUND(#REF!+#REF!+#REF!+预安排!#REF!+#REF!+'6月'!T7,5) | U7: =ROUND(#REF!+#REF!+#REF!+预安排!O6+#REF!+'6月'!U7,5) | V7: =ROUND(#REF!+#REF!+#REF!+预安排!P6+#REF!+'6月'!V7,5) | W7: =ROUND(#REF!+#REF!+#REF!+预安排!Q6+#REF!+'6月'!W7,5) | X7: =ROUND(#REF!+#REF!+#REF!+预安排!R6+#REF!+'6月'!X7,5) | Y7: =ROUND(#REF!+#REF!+#REF!+预安排!S6+#REF!+'6月'!Y7,5) | Z7: =ROUND(#REF!+#REF!+#REF!+预安排!#REF!+#REF!+'6月'!Z7,5) | AA7: =ROUND(#REF!+#REF!+#REF!+预安排!#REF!+#REF!+'6月'!AA7,5) | AB7: =ROUND(#REF!+#REF!+#REF!+预安排!#REF!+#REF!+'6月'!AB7,5) | AC7: C | AD7: 标 | AE7: Brand-Anonymized | AF7: 200 | AG7: =计划!O7-O7 | AH7: =ROUND(AG7/$AH$1,2)
B8: SKU-1DE29866 | C8: 是 | D8: 5 | F8: 是 | H8: 是 | I8: 是 | K8: 是 | L8: 100 | M8: Product-F23B59C1 | N8: 1 | O8: =SUM(P8:AB8) | P8: =ROUND(#REF!+#REF!+#REF!+预安排!F7+#REF!+'6月'!P8,5) | Q8: =ROUND(#REF!+#REF!+#REF!+预安排!#REF!+#REF!+'6月'!Q8,5) | R8: =ROUND(#REF!+#REF!+#REF!+预安排!G7+#REF!+'6月'!R8,5) | S8: =ROUND(#REF!+#REF!+#REF!+预安排!#REF!+#REF!+'6月'!S8,5) | T8: =ROUND(#REF!+#REF!+#REF!+预安排!#REF!+#REF!+'6月'!T8,5) | U8: =ROUND(#REF!+#REF!+#REF!+预安排!O7+#REF!+'6月'!U8,5) | V8: =ROUND(#REF!+#REF!+#REF!+预安排!P7+#REF!+'6月'!V8,5) | W8: =ROUND(#REF!+#REF!+#REF!+预安排!Q7+#REF!+'6月'!W8,5) | X8: =ROUND(#REF!+#REF!+#REF!+预安排!R7+#REF!+'6月'!X8,5) | Y8: =ROUND(#REF!+#REF!+#REF!+预安排!S7+#REF!+'6月'!Y8,5) | Z8: =ROUND(#REF!+#REF!+#REF!+预安排!#REF!+#REF!+'6月'!Z8,5) | AA8: =ROUND(#REF!+#REF!+#REF!+预安排!#REF!+#REF!+'6月'!AA8,5) | AB8: =ROUND(#REF!+#REF!+#REF!+预安排!#REF!+#REF!+'6月'!AB8,5) | AC8: X | AD8: 标 | AE8: Brand-Anonymized | AF8: 200 | AG8: =计划!O8-O8 | AH8: =ROUND(AG8/$AH$1,2)
B9: 6 | M9: 北京小计 | O9: =SUM(O3:O8) | P9: =SUM(P3:P8) | Q9: =SUM(Q3:Q8) | R9: =SUM(R3:R8) | S9: =SUM(S3:S8) | T9: =SUM(T3:T8) | U9: =SUM(U3:U8) | V9: =SUM(V3:V8) | ... AC9: =SUM(AC3:AC8) | AG9: =计划!O9-O9 | AH9: =ROUND(AG9/$AH$1,2)
B10: SKU-D208A1F4 | D10: 9 | L10: 100 | M10: Product-DE70A72E | N10: 3 | O10: =SUM(P10:AB10) | P10: =ROUND(#REF!+#REF!+#REF!+预安排!F10+#REF!+'6月'!P10,5) | Q10: =ROUND(#REF!+#REF!+#REF!+预安排!#REF!+#REF!+'6月'!Q10,5) | R10: =ROUND(#REF!+#REF!+#REF!+预安排!G10+#REF!+'6月'!R10,5) | S10: =ROUND(#REF!+#REF!+#REF!+预安排!#REF!+#REF!+'6月'!S10,5) | T10: =ROUND(#REF!+#REF!+#REF!+预安排!#REF!+#REF!+'6月'!T10,5) | U10: =ROUND(#REF!+#REF!+#REF!+预安排!O10+#REF!+'6月'!U10,5) | V10: =ROUND(#REF!+#REF!+#REF!+预安排!P10+#REF!+'6月'!V10,5) | W10: =ROUND(#REF!+#REF!+#REF!+预安排!Q10+#REF!+'6月'!W10,5) | X10: =ROUND(#REF!+#REF!+#REF!+预安排!R10+#REF!+'6月'!X10,5) | Y10: =ROUND(#REF!+#REF!+#REF!+预安排!S10+#REF!+'6月'!Y10,5) | Z10: =ROUND(#REF!+#REF!+#REF!+预安排!#REF!+#REF!+'6月'!Z10,5) | AA10: =ROUND(#REF!+#REF!+#REF!+预安排!#REF!+#REF!+'6月'!AA10,5) | AB10: =ROUND(#REF!+#REF!+#REF!+预安排!#REF!+#REF!+'6月'!AB10,5) | AC10: T | AE10: Brand-Anonymized | AF10: 200 | AG10: =计划!O10-O10 | AH10: =ROUND(AG10/$AH$1,2)
B11: SKU-07FCDFBC | D11: 10 | G11: 是 | I11: 是 | L11: 100 | M11: Product-7A1FEE2B | N11: 1 | O11: =SUM(P11:AB11) | P11: =ROUND(#REF!+#REF!+#REF!+预安排!F11+#REF!+'6月'!P11,5) | Q11: =ROUND(#REF!+#REF!+#REF!+预安排!#REF!+#REF!+'6月'!Q11,5) | R11: =ROUND(#REF!+#REF!+#REF!+预安排!G11+#REF!+'6月'!R11,5) | S11: =ROUND(#REF!+#REF!+#REF!+预安排!#REF!+#REF!+'6月'!S11,5) | T11: =ROUND(#REF!+#REF!+#REF!+预安排!#REF!+#REF!+'6月'!T11,5) | U11: =ROUND(#REF!+#REF!+#REF!+预安排!O11+#REF!+'6月'!U11,5) | V11: =ROUND(#REF!+#REF!+#REF!+预安排!P11+#REF!+'6月'!V11,5) | W11: =ROUND(#REF!+#REF!+#REF!+预安排!Q11+#REF!+'6月'!W11,5) | X11: =ROUND(#REF!+#REF!+#REF!+预安排!R11+#REF!+'6月'!X11,5) | Y11: =ROUND(#REF!+#REF!+#REF!+预安排!S11+#REF!+'6月'!Y11,5) | Z11: =ROUND(#REF!+#REF!+#REF!+预安排!#REF!+#REF!+'6月'!Z11,5) | AA11: =ROUND(#REF!+#REF!+#REF!+预安排!#REF!+#REF!+'6月'!AA11,5) | AB11: =ROUND(#REF!+#REF!+#REF!+预安排!#REF!+#REF!+'6月'!AB11,5) | AD11: 标 | AE11: Brand-Anonymized | AF11: 200 | AG11: =计划!O11-O11 | AH11: =ROUND(AG11/$AH$1,2)
B12: SKU-F24DC4CC | D12: 10 | L12: 100 | M12: Product-3F617BC6 | N12: 1 | O12: =SUM(P12:AB12) | P12: =ROUND(#REF!+#REF!+#REF!+预安排!F12+#REF!+'6月'!P12,5) | Q12: =ROUND(#REF!+#REF!+#REF!+预安排!#REF!+#REF!+'6月'!Q12,5) | R12: =ROUND(#REF!+#REF!+#REF!+预安排!G12+#REF!+'6月'!R12,5) | S12: =ROUND(#REF!+#REF!+#REF!+预安排!#REF!+#REF!+'6月'!S12,5) | T12: =ROUND(#REF!+#REF!+#REF!+预安排!#REF!+#REF!+'6月'!T12,5) | U12: =ROUND(#REF!+#REF!+#REF!+预安排!O12+#REF!+'6月'!U12,5) | V12: =ROUND(#REF!+#REF!+#REF!+预安排!P12+#REF!+'6月'!V12,5) | W12: =ROUND(#REF!+#REF!+#REF!+预安排!Q12+#REF!+'6月'!W12,5) | X12: =ROUND(#REF!+#REF!+#REF!+预安排!R12+#REF!+'6月'!X12,5) | Y12: =ROUND(#REF!+#REF!+#REF!+预安排!S12+#REF!+'6月'!Y12,5) | Z12: =ROUND(#REF!+#REF!+#REF!+预安排!#REF!+#REF!+'6月'!Z12,5) | AA12: =ROUND(#REF!+#REF!+#REF!+预安排!#REF!+#REF!+'6月'!AA12,5) | AB12: =ROUND(#REF!+#REF!+#REF!+预安排!#REF!+#REF!+'6月'!AB12,5) | AD12: 方 | AE12: Brand-Anonymized | AF12: 200 | AG12: =计划!O12-O12 | AH12: =ROUND(AG12/$AH$1,2)
B13: SKU-D943D84F | D13: 10 | L13: 100 | M13: Product-9C089579 | N13: 1 | O13: =SUM(P13:AB13) | P13: =ROUND(#REF!+#REF!+#REF!+预安排!F13+#REF!+'6月'!P13,5) | Q13: =ROUND(#REF!+#REF!+#REF!+预安排!#REF!+#REF!+'6月'!Q13,5) | R13: =ROUND(#REF!+#REF!+#REF!+预安排!G13+#REF!+'6月'!R13,5) | S13: =ROUND(#REF!+#REF!+#REF!+预安排!#REF!+#REF!+'6月'!S13,5) | T13: =ROUND(#REF!+#REF!+#REF!+预安排!#REF!+#REF!+'6月'!T13,5) | U13: =ROUND(#REF!+#REF!+#REF!+预安排!O13+#REF!+'6月'!U13,5) | V13: =ROUND(#REF!+#REF!+#REF!+预安排!P13+#REF!+'6月'!V13,5) | W13: =ROUND(#REF!+#REF!+#REF!+预安排!Q13+#REF!+'6月'!W13,5) | X13: =ROUND(#REF!+#REF!+#REF!+预安排!R13+#REF!+'6月'!X13,5) | Y13: =ROUND(#REF!+#REF!+#REF!+预安排!S13+#REF!+'6月'!Y13,5) | Z13: =ROUND(#REF!+#REF!+#REF!+预安排!#REF!+#REF!+'6月'!Z13,5) | AA13: =ROUND(#REF!+#REF!+#REF!+预安排!#REF!+#REF!+'6月'!AA13,5) | AB13: =ROUND(#REF!+#REF!+#REF!+预安排!#REF!+#REF!+'6月'!AB13,5) | AE13: Brand-Anonymized | AF13: 200 | AG13: =计划!O13-O13 | AH13: =ROUND(AG13/$AH$1,2)
B14: SKU-6D9E63BD | D14: 8 | F14: 是 | I14: 是 | L14: 100 | M14: Product-BC499EF2 | N14: 1 | O14: =SUM(P14:AB14) | P14: =ROUND(#REF!+#REF!+#REF!+预安排!F14+#REF!+'6月'!P14,5) | Q14: =ROUND(#REF!+#REF!+#REF!+预安排!#REF!+#REF!+'6月'!Q14,5) | R14: =ROUND(#REF!+#REF!+#REF!+预安排!G14+#REF!+'6月'!R14,5) | S14: =ROUND(#REF!+#REF!+#REF!+预安排!#REF!+#REF!+'6月'!S14,5) | T14: =ROUND(#REF!+#REF!+#REF!+预安排!#REF!+#REF!+'6月'!T14,5) | U14: =ROUND(#REF!+#REF!+#REF!+预安排!O14+#REF!+'6月'!U14,5) | V14: =ROUND(#REF!+#REF!+#REF!+预安排!P14+#REF!+'6月'!V14,5) | W14: =ROUND(#REF!+#REF!+#REF!+预安排!Q14+#REF!+'6月'!W14,5) | X14: =ROUND(#REF!+#REF!+#REF!+预安排!R14+#REF!+'6月'!X14,5) | Y14: =ROUND(#REF!+#REF!+#REF!+预安排!S14+#REF!+'6月'!Y14,5) | Z14: =ROUND(#REF!+#REF!+#REF!+预安排!#REF!+#REF!+'6月'!Z14,5) | AA14: =ROUND(#REF!+#REF!+#REF!+预安排!#REF!+#REF!+'6月'!AA14,5) | AB14: =ROUND(#REF!+#REF!+#REF!+预安排!#REF!+#REF!+'6月'!AB14,5) | AC14: C | AD14: 方 | AE14: Brand-Anonymized | AF14: 200 | AG14: =计划!O14-O14 | AH14: =ROUND(AG14/$AH$1,2)
B15: SKU-01FF2431 | D15: 8 | F15: 是 | I15: 是 | L15: 100 | M15: Product-C54A353F | N15: 1 | O15: =SUM(P15:AB15) | P15: =ROUND(#REF!+#REF!+#REF!+预安排!F15+#REF!+'6月'!P15,5) | Q15: =ROUND(#REF!+#REF!+#REF!+预安排!#REF!+#REF!+'6月'!Q15,5) | R15: =ROUND(#REF!+#REF!+#REF!+预安排!G15+#REF!+'6月'!R15,5) | S15: =ROUND(#REF!+#REF!+#REF!+预安排!#REF!+#REF!+'6月'!S15,5) | T15: =ROUND(#REF!+#REF!+#REF!+预安排!#REF!+#REF!+'6月'!T15,5) | U15: =ROUND(#REF!+#REF!+#REF!+预安排!O15+#REF!+'6月'!U15,5) | V15: =ROUND(#REF!+#REF!+#REF!+预安排!P15+#REF!+'6月'!V15,5) | W15: =ROUND(#REF!+#REF!+#REF!+预安排!Q15+#REF!+'6月'!W15,5) | X15: =ROUND(#REF!+#REF!+#REF!+预安排!R15+#REF!+'6月'!X15,5) | Y15: =ROUND(#REF!+#REF!+#REF!+预安排!S15+#REF!+'6月'!Y15,5) | Z15: =ROUND(#REF!+#REF!+#REF!+预安排!#REF!+#REF!+'6月'!Z15,5) | AA15: =ROUND(#REF!+#REF!+#REF!+预安排!#REF!+#REF!+'6月'!AA15,5) | AB15: =ROUND(#REF!+#REF!+#REF!+预安排!#REF!+#REF!+'6月'!AB15,5) | AC15: C | AD15: 标 | AE15: Brand-Anonymized | AF15: 200 | AG15: =计划!O15-O15 | AH15: =ROUND(AG15/$AH$1,2)
B16: SKU-8916FAEC | D16: 8 | F16: 是 | I16: 是 | J16: 共 | L16: 100 | M16: Product-558A622A | N16: 1 | O16: =SUM(P16:AB16) | P16: =ROUND(#REF!+#REF!+#REF!+预安排!F16+#REF!+'6月'!P16,5) | Q16: =ROUND(#REF!+#REF!+#REF!+预安排!#REF!+#REF!+'6月'!Q16,5) | R16: =ROUND(#REF!+#REF!+#REF!+预安排!G16+#REF!+'6月'!R16,5) | S16: =ROUND(#REF!+#REF!+#REF!+预安排!#REF!+#REF!+'6月'!S16,5) | T16: =ROUND(#REF!+#REF!+#REF!+预安排!#REF!+#REF!+'6月'!T16,5) | U16: =ROUND(#REF!+#REF!+#REF!+预安排!O16+#REF!+'6月'!U16,5) | V16: =ROUND(#REF!+#REF!+#REF!+预安排!P16+#REF!+'6月'!V16,5) | W16: =ROUND(#REF!+#REF!+#REF!+预安排!Q16+#REF!+'6月'!W16,5) | X16: =ROUND(#REF!+#REF!+#REF!+预安排!R16+#REF!+'6月'!X16,5) | Y16: =ROUND(#REF!+#REF!+#REF!+预安排!S16+#REF!+'6月'!Y16,5) | Z16: =ROUND(#REF!+#REF!+#REF!+预安排!#REF!+#REF!+'6月'!Z16,5) | AA16: =ROUND(#REF!+#REF!+#REF!+预安排!#REF!+#REF!+'6月'!AA16,5) | AB16: =ROUND(#REF!+#REF!+#REF!+预安排!#REF!+#REF!+'6月'!AB16,5) | AC16: C | AD16: 长 | AE16: Brand-Anonymized | AF16: 200 | AG16: =计划!O16-O16 | AH16: =ROUND(AG16/$AH$1,2)
B17: SKU-13F48E9F | D17: 8 | F17: 是 | I17: 是 | L17: 100 | M17: Product-9B1626A5 | N17: 1 | O17: =SUM(P17:AB17) | P17: =ROUND(#REF!+#REF!+#REF!+预安排!F17+#REF!+'6月'!P17,5) | Q17: =ROUND(#REF!+#REF!+#REF!+预安排!#REF!+#REF!+'6月'!Q17,5) | R17: =ROUND(#REF!+#REF!+#REF!+预安排!G17+#REF!+'6月'!R17,5) | S17: =ROUND(#REF!+#REF!+#REF!+预安排!#REF!+#REF!+'6月'!S17,5) | T17: =ROUND(#REF!+#REF!+#REF!+预安排!#REF!+#REF!+'6月'!T17,5) | U17: =ROUND(#REF!+#REF!+#REF!+预安排!O17+#REF!+'6月'!U17,5) | V17: =ROUND(#REF!+#REF!+#REF!+预安排!P17+#REF!+'6月'!V17,5) | W17: =ROUND(#REF!+#REF!+#REF!+预安排!Q17+#REF!+'6月'!W17,5) | X17: =ROUND(#REF!+#REF!+#REF!+预安排!R17+#REF!+'6月'!X17,5) | Y17: =ROUND(#REF!+#REF!+#REF!+预安排!S17+#REF!+'6月'!Y17,5) | Z17: =ROUND(#REF!+#REF!+#REF!+预安排!#REF!+#REF!+'6月'!Z17,5) | AA17: =ROUND(#REF!+#REF!+#REF!+预安排!#REF!+#REF!+'6月'!AA17,5) | AB17: =ROUND(#REF!+#REF!+#REF!+预安排!#REF!+#REF!+'6月'!AB17,5) | AC17: C | AD17: 长 | AE17: Brand-Anonymized | AF17: 200 | AG17: =计划!O17-O17 | AH17: =ROUND(AG17/$AH$1,2)
B18: SKU-84735B62 | C18: 是 | D18: 10 | L18: 100 | M18: Product-61AE19F7 | N18: 3 | O18: =SUM(P18:AB18) | P18: =ROUND(#REF!+#REF!+#REF!+预安排!F18+#REF!+'6月'!P18,5) | Q18: =ROUND(#REF!+#REF!+#REF!+预安排!#REF!+#REF!+'6月'!Q18,5) | R18: =ROUND(#REF!+#REF!+#REF!+预安排!G18+#REF!+'6月'!R18,5) | S18: =ROUND(#REF!+#REF!+#REF!+预安排!#REF!+#REF!+'6月'!S18,5) | T18: =ROUND(#REF!+#REF!+#REF!+预安排!#REF!+#REF!+'6月'!T18,5) | U18: =ROUND(#REF!+#REF!+#REF!+预安排!O18+#REF!+'6月'!U18,5) | V18: =ROUND(#REF!+#REF!+#REF!+预安排!P18+#REF!+'6月'!V18,5) | W18: =ROUND(#REF!+#REF!+#REF!+预安排!Q18+#REF!+'6月'!W18,5) | X18: =ROUND(#REF!+#REF!+#REF!+预安排!R18+#REF!+'6月'!X18,5) | Y18: =ROUND(#REF!+#REF!+#REF!+预安排!S18+#REF!+'6月'!Y18,5) | Z18: =ROUND(#REF!+#REF!+#REF!+预安排!#REF!+#REF!+'6月'!Z18,5) | AA18: =ROUND(#REF!+#REF!+#REF!+预安排!#REF!+#REF!+'6月'!AA18,5) | AB18: =ROUND(#REF!+#REF!+#REF!+预安排!#REF!+#REF!+'6月'!AB18,5) | AC18: T | AE18: Brand-Anonymized | AF18: 200 | AG18: =计划!O18-O18 | AH18: =ROUND(AG18/$AH$1,2)
B19: SKU-9356910A | C19: 是 | D19: 11 | L19: 100 | M19: Product-1433AC24 | N19: 2 | O19: =SUM(P19:AB19) | P19: =ROUND(#REF!+#REF!+#REF!+预安排!F19+#REF!+'6月'!P19,5) | Q19: =ROUND(#REF!+#REF!+#REF!+预安排!#REF!+#REF!+'6月'!Q19,5) | R19: =ROUND(#REF!+#REF!+#REF!+预安排!G19+#REF!+'6月'!R19,5) | S19: =ROUND(#REF!+#REF!+#REF!+预安排!#REF!+#REF!+'6月'!S19,5) | T19: =ROUND(#REF!+#REF!+#REF!+预安排!#REF!+#REF!+'6月'!T19,5) | U19: =ROUND(#REF!+#REF!+#REF!+预安排!O19+#REF!+'6月'!U19,5) | V19: =ROUND(#REF!+#REF!+#REF!+预安排!P19+#REF!+'6月'!V19,5) | W19: =ROUND(#REF!+#REF!+#REF!+预安排!Q19+#REF!+'6月'!W19,5) | X19: =ROUND(#REF!+#REF!+#REF!+预安排!R19+#REF!+'6月'!X19,5) | Y19: =ROUND(#REF!+#REF!+#REF!+预安排!S19+#REF!+'6月'!Y19,5) | Z19: =ROUND(#REF!+#REF!+#REF!+预安排!#REF!+#REF!+'6月'!Z19,5) | AA19: =ROUND(#REF!+#REF!+#REF!+预安排!#REF!+#REF!+'6月'!AA19,5) | AB19: =ROUND(#REF!+#REF!+#REF!+预安排!#REF!+#REF!+'6月'!AB19,5) | AC19: T | AE19: Brand-Anonymized | AF19: 200 | AG19: =计划!O19-O19 | AH19: =ROUND(AG19/$AH$1,2)
B20: SKU-A1C9F3C5 | C20: 是 | D20: 10 | J20: 共 | L20: 100 | M20: Product-A7F669A5 | N20: 2 | O20: =SUM(P20:AB20) | P20: =ROUND(#REF!+#REF!+#REF!+预安排!F20+#REF!+'6月'!P20,5) | Q20: =ROUND(#REF!+#REF!+#REF!+预安排!#REF!+#REF!+'6月'!Q20,5) | R20: =ROUND(#REF!+#REF!+#REF!+预安排!G20+#REF!+'6月'!R20,5) | S20: =ROUND(#REF!+#REF!+#REF!+预安排!#REF!+#REF!+'6月'!S20,5) | T20: =ROUND(#REF!+#REF!+#REF!+预安排!#REF!+#REF!+'6月'!T20,5) | U20: =ROUND(#REF!+#REF!+#REF!+预安排!O20+#REF!+'6月'!U20,5) | V20: =ROUND(#REF!+#REF!+#REF!+预安排!P20+#REF!+'6月'!V20,5) | W20: =ROUND(#REF!+#REF!+#REF!+预安排!Q20+#REF!+'6月'!W20,5) | X20: =ROUND(#REF!+#REF!+#REF!+预安排!R20+#REF!+'6月'!X20,5) | Y20: =ROUND(#REF!+#REF!+#REF!+预安排!S20+#REF!+'6月'!Y20,5) | Z20: =ROUND(#REF!+#REF!+#REF!+预安排!#REF!+#REF!+'6月'!Z20,5) | AA20: =ROUND(#REF!+#REF!+#REF!+预安排!#REF!+#REF!+'6月'!AA20,5) | AB20: =ROUND(#REF!+#REF!+#REF!+预安排!#REF!+#REF!+'6月'!AB20,5) | AC20: T | AE20: Brand-Anonymized | AF20: 200 | AG20: =计划!O20-O20 | AH20: =ROUND(AG20/$AH$1,2)
B21: SKU-9FED3CD7 | C21: 是 | D21: 6 | E21: 是 | I21: 是 | L21: 100 | M21: Product-80F515FA | N21: 1 | O21: =SUM(P21:AB21) | P21: =ROUND(#REF!+#REF!+#REF!+预安排!F21+#REF!+'6月'!P21,5) | Q21: =ROUND(#REF!+#REF!+#REF!+预安排!#REF!+#REF!+'6月'!Q21,5) | R21: =ROUND(#REF!+#REF!+#REF!+预安排!G21+#REF!+'6月'!R21,5) | S21: =ROUND(#REF!+#REF!+#REF!+预安排!#REF!+#REF!+'6月'!S21,5) | T21: =ROUND(#REF!+#REF!+#REF!+预安排!#REF!+#REF!+'6月'!T21,5) | U21: =ROUND(#REF!+#REF!+#REF!+预安排!O21+#REF!+'6月'!U21,5) | V21: =ROUND(#REF!+#REF!+#REF!+预安排!P21+#REF!+'6月'!V21,5) | W21: =ROUND(#REF!+#REF!+#REF!+预安排!Q21+#REF!+'6月'!W21,5) | X21: =ROUND(#REF!+#REF!+#REF!+预安排!R21+#REF!+'6月'!X21,5) | Y21: =ROUND(#REF!+#REF!+#REF!+预安排!S21+#REF!+'6月'!Y21,5) | Z21: =ROUND(#REF!+#REF!+#REF!+预安排!#REF!+#REF!+'6月'!Z21,5) | AA21: =ROUND(#REF!+#REF!+#REF!+预安排!#REF!+#REF!+'6月'!AA21,5) | AB21: =ROUND(#REF!+#REF!+#REF!+预安排!#REF!+#REF!+'6月'!AB21,5) | AD21: 方 | AE21: Brand-Anonymized | AF21: 200 | AG21: =计划!O21-O21 | AH21: =ROUND(AG21/$AH$1,2)
B22: SKU-D2D4FD85 | C22: 是 | D22: 8 | E22: 是 | I22: 是 | L22: 100 | M22: Product-D1D130D9 | N22: 1 | O22: =SUM(P22:AB22) | P22: =ROUND(#REF!+#REF!+#REF!+预安排!F22+#REF!+'6月'!P22,5) | Q22: =ROUND(#REF!+#REF!+#REF!+预安排!#REF!+#REF!+'6月'!Q22,5) | R22: =ROUND(#REF!+#REF!+#REF!+预安排!G22+#REF!+'6月'!R22,5) | S22: =ROUND(#REF!+#REF!+#REF!+预安排!#REF!+#REF!+'6月'!S22,5) | T22: =ROUND(#REF!+#REF!+#REF!+预安排!#REF!+#REF!+'6月'!T22,5) | U22: =ROUND(#REF!+#REF!+#REF!+预安排!O22+#REF!+'6月'!U22,5) | V22: =ROUND(#REF!+#REF!+#REF!+预安排!P22+#REF!+'6月'!V22,5) | W22: =ROUND(#REF!+#REF!+#REF!+预安排!Q22+#REF!+'6月'!W22,5) | X22: =ROUND(#REF!+#REF!+#REF!+预安排!R22+#REF!+'6月'!X22,5) | Y22: =ROUND(#REF!+#REF!+#REF!+预安排!S22+#REF!+'6月'!Y22,5) | Z22: =ROUND(#REF!+#REF!+#REF!+预安排!#REF!+#REF!+'6月'!Z22,5) | AA22: =ROUND(#REF!+#REF!+#REF!+预安排!#REF!+#REF!+'6月'!AA22,5) | AB22: =ROUND(#REF!+#REF!+#REF!+预安排!#REF!+#REF!+'6月'!AB22,5) | AE22: Brand-Anonymized | AF22: 200 | AG22: =计划!O22-O22 | AH22: =ROUND(AG22/$AH$1,2)
B23: SKU-2324D87D | C23: 是 | D23: 9 | F23: 是 | I23: 是 | L23: 100 | M23: Product-142947AA | N23: 1 | O23: =SUM(P23:AB23) | P23: =ROUND(#REF!+#REF!+#REF!+预安排!F23+#REF!+'6月'!P23,5) | Q23: =ROUND(#REF!+#REF!+#REF!+预安排!#REF!+#REF!+'6月'!Q23,5) | R23: =ROUND(#REF!+#REF!+#REF!+预安排!G23+#REF!+'6月'!R23,5) | S23: =ROUND(#REF!+#REF!+#REF!+预安排!#REF!+#REF!+'6月'!S23,5) | T23: =ROUND(#REF!+#REF!+#REF!+预安排!#REF!+#REF!+'6月'!T23,5) | U23: =ROUND(#REF!+#REF!+#REF!+预安排!O23+#REF!+'6月'!U23,5) | V23: =ROUND(#REF!+#REF!+#REF!+预安排!P23+#REF!+'6月'!V23,5) | W23: =ROUND(#REF!+#REF!+#REF!+预安排!Q23+#REF!+'6月'!W23,5) | X23: =ROUND(#REF!+#REF!+#REF!+预安排!R23+#REF!+'6月'!X23,5) | Y23: =ROUND(#REF!+#REF!+#REF!+预安排!S23+#REF!+'6月'!Y23,5) | Z23: =ROUND(#REF!+#REF!+#REF!+预安排!#REF!+#REF!+'6月'!Z23,5) | AA23: =ROUND(#REF!+#REF!+#REF!+预安排!#REF!+#REF!+'6月'!AA23,5) | AB23: =ROUND(#REF!+#REF!+#REF!+预安排!#REF!+#REF!+'6月'!AB23,5) | AC23: C | AD23: 长 | AE23: Brand-Anonymized | AF23: 200 | AG23: =计划!O23-O23 | AH23: =ROUND(AG23/$AH$1,2)
B24: SKU-D3A8D0D1 | C24: 是 | D24: 9 | F24: 是 | I24: 是 | L24: 100 | M24: Product-B80128BB | N24: 1 | O24: =SUM(P24:AB24) | P24: =ROUND(#REF!+#REF!+#REF!+预安排!F24+#REF!+'6月'!P24,5) | Q24: =ROUND(#REF!+#REF!+#REF!+预安排!#REF!+#REF!+'6月'!Q24,5) | R24: =ROUND(#REF!+#REF!+#REF!+预安排!G24+#REF!+'6月'!R24,5) | S24: =ROUND(#REF!+#REF!+#REF!+预安排!#REF!+#REF!+'6月'!S24,5) | T24: =ROUND(#REF!+#REF!+#REF!+预安排!#REF!+#REF!+'6月'!T24,5) | U24: =ROUND(#REF!+#REF!+#REF!+预安排!O24+#REF!+'6月'!U24,5) | V24: =ROUND(#REF!+#REF!+#REF!+预安排!P24+#REF!+'6月'!V24,5) | W24: =ROUND(#REF!+#REF!+#REF!+预安排!Q24+#REF!+'6月'!W24,5) | X24: =ROUND(#REF!+#REF!+#REF!+预安排!R24+#REF!+'6月'!X24,5) | Y24: =ROUND(#REF!+#REF!+#REF!+预安排!S24+#REF!+'6月'!Y24,5) | Z24: =ROUND(#REF!+#REF!+#REF!+预安排!#REF!+#REF!+'6月'!Z24,5) | AA24: =ROUND(#REF!+#REF!+#REF!+预安排!#REF!+#REF!+'6月'!AA24,5) | AB24: =ROUND(#REF!+#REF!+#REF!+预安排!#REF!+#REF!+'6月'!AB24,5) | AC24: X | AD24: 长 | AE24: Brand-Anonymized | AF24: 200 | AG24: =计划!O24-O24 | AH24: =ROUND(AG24/$AH$1,2)
B25: SKU-55B49425 | C25: 是 | D25: 11 | J25: 共 | L25: 100 | M25: Product-2E005B6F | N25: 1 | O25: =SUM(P25:AB25) | P25: =ROUND(#REF!+#REF!+#REF!+预安排!F29+#REF!+'6月'!P25,5) | Q25: =ROUND(#REF!+#REF!+#REF!+预安排!#REF!+#REF!+'6月'!Q25,5) | R25: =ROUND(#REF!+#REF!+#REF!+预安排!G29+#REF!+'6月'!R25,5) | S25: =ROUND(#REF!+#REF!+#REF!+预安排!#REF!+#REF!+'6月'!S25,5) | T25: =ROUND(#REF!+#REF!+#REF!+预安排!#REF!+#REF!+'6月'!T25,5) | U25: =ROUND(#REF!+#REF!+#REF!+预安排!O29+#REF!+'6月'!U25,5) | V25: =ROUND(#REF!+#REF!+#REF!+预安排!P29+#REF!+'6月'!V25,5) | W25: =ROUND(#REF!+#REF!+#REF!+预安排!Q29+#REF!+'6月'!W25,5) | X25: =ROUND(#REF!+#REF!+#REF!+预安排!R29+#REF!+'6月'!X25,5) | Y25: =ROUND(#REF!+#REF!+#REF!+预安排!S29+#REF!+'6月'!Y25,5) | Z25: =ROUND(#REF!+#REF!+#REF!+预安排!#REF!+#REF!+'6月'!Z25,5) | AA25: =ROUND(#REF!+#REF!+#REF!+预安排!#REF!+#REF!+'6月'!AA25,5) | AB25: =ROUND(#REF!+#REF!+#REF!+预安排!#REF!+#REF!+'6月'!AB25,5) | AC25: T | AE25: Brand-Anonymized | AF25: 200 | AG25: =计划!O25-O25 | AH25: =ROUND(AG25/$AH$1,2)
B26: SKU-7E7C0C23 | C26: 是 | D26: 11 | J26: 共 | L26: 100 | M26: Product-8C5BA899 | N26: 1 | O26: =SUM(P26:AB26) | P26: =ROUND(#REF!+#REF!+#REF!+预安排!F30+#REF!+'6月'!P26,5) | Q26: =ROUND(#REF!+#REF!+#REF!+预安排!#REF!+#REF!+'6月'!Q26,5) | R26: =ROUND(#REF!+#REF!+#REF!+预安排!G30+#REF!+'6月'!R26,5) | S26: =ROUND(#REF!+#REF!+#REF!+预安排!#REF!+#REF!+'6月'!S26,5) | T26: =ROUND(#REF!+#REF!+#REF!+预安排!#REF!+#REF!+'6月'!T26,5) | U26: =ROUND(#REF!+#REF!+#REF!+预安排!O30+#REF!+'6月'!U26,5) | V26: =ROUND(#REF!+#REF!+#REF!+预安排!P30+#REF!+'6月'!V26,5) | W26: =ROUND(#REF!+#REF!+#REF!+预安排!Q30+#REF!+'6月'!W26,5) | X26: =ROUND(#REF!+#REF!+#REF!+预安排!R30+#REF!+'6月'!X26,5) | Y26: =ROUND(#REF!+#REF!+#REF!+预安排!S30+#REF!+'6月'!Y26,5) | Z26: =ROUND(#REF!+#REF!+#REF!+预安排!#REF!+#REF!+'6月'!Z26,5) | AA26: =ROUND(#REF!+#REF!+#REF!+预安排!#REF!+#REF!+'6月'!AA26,5) | AB26: =ROUND(#REF!+#REF!+#REF!+预安排!#REF!+#REF!+'6月'!AB26,5) | AC26: T | AE26: Brand-Anonymized | AF26: 200 | AG26: =计划!O26-O26 | AH26: =ROUND(AG26/$AH$1,2)
B27: SKU-581048FF | C27: 是 | D27: 11 | L27: 100 | M27: Product-9C9F0DD0 | N27: 1 | O27: =SUM(P27:AB27) | P27: =ROUND(#REF!+#REF!+#REF!+预安排!F31+#REF!+'6月'!P27,5) | Q27: =ROUND(#REF!+#REF!+#REF!+预安排!#REF!+#REF!+'6月'!Q27,5) | R27: =ROUND(#REF!+#REF!+#REF!+预安排!G31+#REF!+'6月'!R27,5) | S27: =ROUND(#REF!+#REF!+#REF!+预安排!#REF!+#REF!+'6月'!S27,5) | T27: =ROUND(#REF!+#REF!+#REF!+预安排!#REF!+#REF!+'6月'!T27,5) | U27: =ROUND(#REF!+#REF!+#REF!+预安排!O31+#REF!+'6月'!U27,5) | V27: =ROUND(#REF!+#REF!+#REF!+预安排!P31+#REF!+'6月'!V27,5) | W27: =ROUND(#REF!+#REF!+#REF!+预安排!Q31+#REF!+'6月'!W27,5) | X27: =ROUND(#REF!+#REF!+#REF!+预安排!R31+#REF!+'6月'!X27,5) | Y27: =ROUND(#REF!+#REF!+#REF!+预安排!S31+#REF!+'6月'!Y27,5) | Z27: =ROUND(#REF!+#REF!+#REF!+预安排!#REF!+#REF!+'6月'!Z27,5) | AA27: =ROUND(#REF!+#REF!+#REF!+预安排!#REF!+#REF!+'6月'!AA27,5) | AB27: =ROUND(#REF!+#REF!+#REF!+预安排!#REF!+#REF!+'6月'!AB27,5) | AC27: C | AD27: 方 | AE27: Brand-Anonymized | AF27: 200 | AG27: =计划!O27-O27 | AH27: =ROUND(AG27/$AH$1,2)
B28: SKU-1943C75B | C28: 是 | D28: 10 | F28: 是 | I28: 是 | J28: 共 | L28: 100 | M28: Product-62BC29B7 | N28: 1 | O28: =SUM(P28:AB28) | P28: =ROUND(#REF!+#REF!+#REF!+预安排!F32+#REF!+'6月'!P28,5) | Q28: =ROUND(#REF!+#REF!+#REF!+预安排!#REF!+#REF!+'6月'!Q28,5) | R28: =ROUND(#REF!+#REF!+#REF!+预安排!G32+#REF!+'6月'!R28,5) | S28: =ROUND(#REF!+#REF!+#REF!+预安排!#REF!+#REF!+'6月'!S28,5) | T28: =ROUND(#REF!+#REF!+#REF!+预安排!#REF!+#REF!+'6月'!T28,5) | U28: =ROUND(#REF!+#REF!+#REF!+预安排!O32+#REF!+'6月'!U28,5) | V28: =ROUND(#REF!+#REF!+#REF!+预安排!P32+#REF!+'6月'!V28,5) | W28: =ROUND(#REF!+#REF!+#REF!+预安排!Q32+#REF!+'6月'!W28,5) | X28: =ROUND(#REF!+#REF!+#REF!+预安排!R32+#REF!+'6月'!X28,5) | Y28: =ROUND(#REF!+#REF!+#REF!+预安排!S32+#REF!+'6月'!Y28,5) | Z28: =ROUND(#REF!+#REF!+#REF!+预安排!#REF!+#REF!+'6月'!Z28,5) | AA28: =ROUND(#REF!+#REF!+#REF!+预安排!#REF!+#REF!+'6月'!AA28,5) | AB28: =ROUND(#REF!+#REF!+#REF!+预安排!#REF!+#REF!+'6月'!AB28,5) | AC28: C | AD28: 方 | AE28: Brand-Anonymized | AF28: 200 | AG28: =计划!O28-O28 | AH28: =ROUND(AG28/$AH$1,2)
B29: SKU-51C641E5 | C29: 是 | D29: 10 | F29: 是 | I29: 是 | J29: 共 | L29: 100 | M29: Product-4CA63C06 | N29: 1 | O29: =SUM(P29:AB29) | P29: =ROUND(#REF!+#REF!+#REF!+预安排!F33+#REF!+'6月'!P29,5) | Q29: =ROUND(#REF!+#REF!+#REF!+预安排!#REF!+#REF!+'6月'!Q29,5) | R29: =ROUND(#REF!+#REF!+#REF!+预安排!G33+#REF!+'6月'!R29,5) | S29: =ROUND(#REF!+#REF!+#REF!+预安排!#REF!+#REF!+'6月'!S29,5) | T29: =ROUND(#REF!+#REF!+#REF!+预安排!#REF!+#REF!+'6月'!T29,5) | U29: =ROUND(#REF!+#REF!+#REF!+预安排!O33+#REF!+'6月'!U29,5) | V29: =ROUND(#REF!+#REF!+#REF!+预安排!P33+#REF!+'6月'!V29,5) | W29: =ROUND(#REF!+#REF!+#REF!+预安排!Q33+#REF!+'6月'!W29,5) | X29: =ROUND(#REF!+#REF!+#REF!+预安排!R33+#REF!+'6月'!X29,5) | Y29: =ROUND(#REF!+#REF!+#REF!+预安排!S33+#REF!+'6月'!Y29,5) | Z29: =ROUND(#REF!+#REF!+#REF!+预安排!#REF!+#REF!+'6月'!Z29,5) | AA29: =ROUND(#REF!+#REF!+#REF!+预安排!#REF!+#REF!+'6月'!AA29,5) | AB29: =ROUND(#REF!+#REF!+#REF!+预安排!#REF!+#REF!+'6月'!AB29,5) | AC29: T | AD29: 长 | AE29: Brand-Anonymized | AF29: 200 | AG29: =计划!O29-O29 | AH29: =ROUND(AG29/$AH$1,2)
B30: SKU-740A9334 | C30: 是 | D30: 10 | G30: 是 | I30: 是 | L30: 100 | M30: Product-7726A962 | N30: 1 | O30: =SUM(P30:AB30) | P30: =ROUND(#REF!+#REF!+#REF!+预安排!F34+#REF!+'6月'!P30,5) | Q30: =ROUND(#REF!+#REF!+#REF!+预安排!#REF!+#REF!+'6月'!Q30,5) | R30: =ROUND(#REF!+#REF!+#REF!+预安排!G34+#REF!+'6月'!R30,5) | S30: =ROUND(#REF!+#REF!+#REF!+预安排!#REF!+#REF!+'6月'!S30,5) | T30: =ROUND(#REF!+#REF!+#REF!+预安排!#REF!+#REF!+'6月'!T30,5) | U30: =ROUND(#REF!+#REF!+#REF!+预安排!O34+#REF!+'6月'!U30,5) | V30: =ROUND(#REF!+#REF!+#REF!+预安排!P34+#REF!+'6月'!V30,5) | W30: =ROUND(#REF!+#REF!+#REF!+预安排!Q34+#REF!+'6月'!W30,5) | X30: =ROUND(#REF!+#REF!+#REF!+预安排!R34+#REF!+'6月'!X30,5) | Y30: =ROUND(#REF!+#REF!+#REF!+预安排!S34+#REF!+'6月'!Y30,5) | Z30: =ROUND(#REF!+#REF!+#REF!+预安排!#REF!+#REF!+'6月'!Z30,5) | AA30: =ROUND(#REF!+#REF!+#REF!+预安排!#REF!+#REF!+'6月'!AA30,5) | AB30: =ROUND(#REF!+#REF!+#REF!+预安排!#REF!+#REF!+'6月'!AB30,5) | AD30: 方 | AE30: Brand-Anonymized | AF30: 200 | AG30: =计划!O30-O30 | AH30: =ROUND(AG30/$AH$1,2)
B31: SKU-ABAD8823 | C31: 是 | D31: 8 | E31: 是 | I31: 是 | J31: 共 | L31: 100 | M31: Product-342D1F0D | N31: 1 | O31: =SUM(P31:AB31) | P31: =ROUND(#REF!+#REF!+#REF!+预安排!F35+#REF!+'6月'!P31,5) | Q31: =ROUND(#REF!+#REF!+#REF!+预安排!#REF!+#REF!+'6月'!Q31,5) | R31: =ROUND(#REF!+#REF!+#REF!+预安排!G35+#REF!+'6月'!R31,5) | S31: =ROUND(#REF!+#REF!+#REF!+预安排!#REF!+#REF!+'6月'!S31,5) | T31: =ROUND(#REF!+#REF!+#REF!+预安排!#REF!+#REF!+'6月'!T31,5) | U31: =ROUND(#REF!+#REF!+#REF!+预安排!O35+#REF!+'6月'!U31,5) | V31: =ROUND(#REF!+#REF!+#REF!+预安排!P35+#REF!+'6月'!V31,5) | W31: =ROUND(#REF!+#REF!+#REF!+预安排!Q35+#REF!+'6月'!W31,5) | X31: =ROUND(#REF!+#REF!+#REF!+预安排!R35+#REF!+'6月'!X31,5) | Y31: =ROUND(#REF!+#REF!+#REF!+预安排!S35+#REF!+'6月'!Y31,5) | Z31: =ROUND(#REF!+#REF!+#REF!+预安排!#REF!+#REF!+'6月'!Z31,5) | AA31: =ROUND(#REF!+#REF!+#REF!+预安排!#REF!+#REF!+'6月'!AA31,5) | AB31: =ROUND(#REF!+#REF!+#REF!+预安排!#REF!+#REF!+'6月'!AB31,5) | AC31: C | AD31: 细 | AE31: Brand-Anonymized | AF31: 200 | AG31: =计划!O31-O31 | AH31: =ROUND(AG31/$AH$1,2)
B32: SKU-CD40403A | C32: 是 | D32: 8 | E32: 是 | I32: 是 | J32: 共 | L32: 100 | M32: Product-D6D3CCE6 | N32: 1 | O32: =SUM(P32:AB32) | P32: =ROUND(#REF!+#REF!+#REF!+预安排!F36+#REF!+'6月'!P32,5) | Q32: =ROUND(#REF!+#REF!+#REF!+预安排!#REF!+#REF!+'6月'!Q32,5) | R32: =ROUND(#REF!+#REF!+#REF!+预安排!G36+#REF!+'6月'!R32,5) | S32: =ROUND(#REF!+#REF!+#REF!+预安排!#REF!+#REF!+'6月'!S32,5) | T32: =ROUND(#REF!+#REF!+#REF!+预安排!#REF!+#REF!+'6月'!T32,5) | U32: =ROUND(#REF!+#REF!+#REF!+预安排!O36+#REF!+'6月'!U32,5) | V32: =ROUND(#REF!+#REF!+#REF!+预安排!P36+#REF!+'6月'!V32,5) | W32: =ROUND(#REF!+#REF!+#REF!+预安排!Q36+#REF!+'6月'!W32,5) | X32: =ROUND(#REF!+#REF!+#REF!+预安排!R36+#REF!+'6月'!X32,5) | Y32: =ROUND(#REF!+#REF!+#REF!+预安排!S36+#REF!+'6月'!Y32,5) | Z32: =ROUND(#REF!+#REF!+#REF!+预安排!#REF!+#REF!+'6月'!Z32,5) | AA32: =ROUND(#REF!+#REF!+#REF!+预安排!#REF!+#REF!+'6月'!AA32,5) | AB32: =ROUND(#REF!+#REF!+#REF!+预安排!#REF!+#REF!+'6月'!AB32,5) | AC32: C | AD32: 标 | AE32: Brand-Anonymized | AF32: 200 | AG32: =计划!O32-O32 | AH32: =ROUND(AG32/$AH$1,2)
B33: SKU-B0D292B1 | C33: 是 | D33: 10 | G33: 是 | I33: 是 | L33: 100 | M33: Product-7726A962 | N33: 1 | O33: =SUM(P33:AB33) | P33: =ROUND(#REF!+#REF!+#REF!+预安排!F37+#REF!+'6月'!P33,5) | Q33: =ROUND(#REF!+#REF!+#REF!+预安排!#REF!+#REF!+'6月'!Q33,5) | R33: =ROUND(#REF!+#REF!+#REF!+预安排!G37+#REF!+'6月'!R33,5) | S33: =ROUND(#REF!+#REF!+#REF!+预安排!#REF!+#REF!+'6月'!S33,5) | T33: =ROUND(#REF!+#REF!+#REF!+预安排!#REF!+#REF!+'6月'!T33,5) | U33: =ROUND(#REF!+#REF!+#REF!+预安排!O37+#REF!+'6月'!U33,5) | V33: =ROUND(#REF!+#REF!+#REF!+预安排!P37+#REF!+'6月'!V33,5) | W33: =ROUND(#REF!+#REF!+#REF!+预安排!Q37+#REF!+'6月'!W33,5) | X33: =ROUND(#REF!+#REF!+#REF!+预安排!R37+#REF!+'6月'!X33,5) | Y33: =ROUND(#REF!+#REF!+#REF!+预安排!S37+#REF!+'6月'!Y33,5) | Z33: =ROUND(#REF!+#REF!+#REF!+预安排!#REF!+#REF!+'6月'!Z33,5) | AA33: =ROUND(#REF!+#REF!+#REF!+预安排!#REF!+#REF!+'6月'!AA33,5) | AB33: =ROUND(#REF!+#REF!+#REF!+预安排!#REF!+#REF!+'6月'!AB33,5) | AC33: X | AD33: 标 | AE33: Brand-Anonymized | AF33: 200 | AG33: =计划!O33-O33 | AH33: =ROUND(AG33/$AH$1,2)
B34: SKU-D5FB4C4D | D34: 10 | L34: 100 | M34: Product-3DCEC0C0 | N34: 1 | O34: =SUM(P34:AB34) | P34: =ROUND(#REF!+#REF!+#REF!+预安排!F39+#REF!+'6月'!P34,5) | Q34: =ROUND(#REF!+#REF!+#REF!+预安排!#REF!+#REF!+'6月'!Q34,5) | R34: =ROUND(#REF!+#REF!+#REF!+预安排!G39+#REF!+'6月'!R34,5) | S34: =ROUND(#REF!+#REF!+#REF!+预安排!#REF!+#REF!+'6月'!S34,5) | T34: =ROUND(#REF!+#REF!+#REF!+预安排!#REF!+#REF!+'6月'!T34,5) | U34: =ROUND(#REF!+#REF!+#REF!+预安排!O39+#REF!+'6月'!U34,5) | V34: =ROUND(#REF!+#REF!+#REF!+预安排!P39+#REF!+'6月'!V34,5) | W34: =ROUND(#REF!+#REF!+#REF!+预安排!Q39+#REF!+'6月'!W34,5) | X34: =ROUND(#REF!+#REF!+#REF!+预安排!R39+#REF!+'6月'!X34,5) | Y34: =ROUND(#REF!+#REF!+#REF!+预安排!S39+#REF!+'6月'!Y34,5) | Z34: =ROUND(#REF!+#REF!+#REF!+预安排!#REF!+#REF!+'6月'!Z34,5) | AA34: =ROUND(#REF!+#REF!+#REF!+预安排!#REF!+#REF!+'6月'!AA34,5) | AB34: =ROUND(#REF!+#REF!+#REF!+预安排!#REF!+#REF!+'6月'!AB34,5) | AD34: 标 | AE34: Brand-Anonymized | AF34: 200 | AG34: =计划!O34-O34 | AH34: =ROUND(AG34/$AH$1,2)
B35: SKU-DCF98B33 | D35: 10 | L35: 100 | M35: Product-3DCEC0C0 | N35: 1 | O35: =SUM(P35:AB35) | P35: =ROUND(#REF!+#REF!+#REF!+预安排!F40+#REF!+'6月'!P35,5) | Q35: =ROUND(#REF!+#REF!+#REF!+预安排!#REF!+#REF!+'6月'!Q35,5) | R35: =ROUND(#REF!+#REF!+#REF!+预安排!G40+#REF!+'6月'!R35,5) | S35: =ROUND(#REF!+#REF!+#REF!+预安排!#REF!+#REF!+'6月'!S35,5) | T35: =ROUND(#REF!+#REF!+#REF!+预安排!#REF!+#REF!+'6月'!T35,5) | U35: =ROUND(#REF!+#REF!+#REF!+预安排!O40+#REF!+'6月'!U35,5) | V35: =ROUND(#REF!+#REF!+#REF!+预安排!P40+#REF!+'6月'!V35,5) | W35: =ROUND(#REF!+#REF!+#REF!+预安排!Q40+#REF!+'6月'!W35,5) | X35: =ROUND(#REF!+#REF!+#REF!+预安排!R40+#REF!+'6月'!X35,5) | Y35: =ROUND(#REF!+#REF!+#REF!+预安排!S40+#REF!+'6月'!Y35,5) | Z35: =ROUND(#REF!+#REF!+#REF!+预安排!#REF!+#REF!+'6月'!Z35,5) | AA35: =ROUND(#REF!+#REF!+#REF!+预安排!#REF!+#REF!+'6月'!AA35,5) | AB35: =ROUND(#REF!+#REF!+#REF!+预安排!#REF!+#REF!+'6月'!AB35,5) | AC35: X | AD35: 标 | AE35: Brand-Anonymized | AF35: 200 | AG35: =计划!O35-O35 | AH35: =ROUND(AG35/$AH$1,2)
B36: SKU-7ECD2FA6 | D36: 10 | F36: 是 | I36: 是 | L36: 100 | M36: Product-29355C79 | N36: 1 | O36: =SUM(P36:AB36) | P36: =ROUND(#REF!+#REF!+#REF!+预安排!F41+#REF!+'6月'!P36,5) | Q36: =ROUND(#REF!+#REF!+#REF!+预安排!#REF!+#REF!+'6月'!Q36,5) | R36: =ROUND(#REF!+#REF!+#REF!+预安排!G41+#REF!+'6月'!R36,5) | S36: =ROUND(#REF!+#REF!+#REF!+预安排!#REF!+#REF!+'6月'!S36,5) | T36: =ROUND(#REF!+#REF!+#REF!+预安排!#REF!+#REF!+'6月'!T36,5) | U36: =ROUND(#REF!+#REF!+#REF!+预安排!O41+#REF!+'6月'!U36,5) | V36: =ROUND(#REF!+#REF!+#REF!+预安排!P41+#REF!+'6月'!V36,5) | W36: =ROUND(#REF!+#REF!+#REF!+预安排!Q41+#REF!+'6月'!W36,5) | X36: =ROUND(#REF!+#REF!+#REF!+预安排!R41+#REF!+'6月'!X36,5) | Y36: =ROUND(#REF!+#REF!+#REF!+预安排!S41+#REF!+'6月'!Y36,5) | Z36: =ROUND(#REF!+#REF!+#REF!+预安排!#REF!+#REF!+'6月'!Z36,5) | AA36: =ROUND(#REF!+#REF!+#REF!+预安排!#REF!+#REF!+'6月'!AA36,5) | AB36: =ROUND(#REF!+#REF!+#REF!+预安排!#REF!+#REF!+'6月'!AB36,5) | AC36: X | AE36: Brand-Anonymized | AF36: 200 | AG36: =计划!O36-O36 | AH36: =ROUND(AG36/$AH$1,2)
B37: 27 | M37: 津沪小计 | O37: =SUM(O10:O36) | P37: =SUM(P10:P36) | Q37: =SUM(Q10:Q36) | R37: =SUM(R10:R36) | S37: =SUM(S10:S36) | T37: =SUM(T10:T36) | U37: =SUM(U10:U36) | V37: =SUM(V10:V36) | ... AC37: =SUM(AC10:AC36) | AG37: =计划!O37-O37 | AH37: =ROUND(AG37/$AH$1,2)
B38: 33 | M38: 上海小计 | O38: =O9+O37 | P38: =P9+P37 | Q38: =Q9+Q37 | R38: =R9+R37 | S38: =S9+S37 | T38: =T9+T37 | U38: =U9+U37 | V38: =V9+V37 | ... AC38: =AC9+AC37 | AG38: =计划!O38-O38 | AH38: =ROUND(AG38/$AH$1,2)
A39: 河北 | B39: SKU-3095C758 | C39: 是 | D39: 11 | L39: 100 | M39: Product-280802D6 | N39: 4 | O39: =SUM(P39:AB39) | P39: =ROUND(#REF!+#REF!+#REF!+预安排!F44+#REF!+'6月'!P39,5) | Q39: =ROUND(#REF!+#REF!+#REF!+预安排!#REF!+#REF!+'6月'!Q39,5) | R39: =ROUND(#REF!+#REF!+#REF!+预安排!G44+#REF!+'6月'!R39,5) | S39: =ROUND(#REF!+#REF!+#REF!+预安排!#REF!+#REF!+'6月'!S39,5) | T39: =ROUND(#REF!+#REF!+#REF!+预安排!#REF!+#REF!+'6月'!T39,5) | U39: =ROUND(#REF!+#REF!+#REF!+预安排!O44+#REF!+'6月'!U39,5) | V39: =ROUND(#REF!+#REF!+#REF!+预安排!P44+#REF!+'6月'!V39,5) | W39: =ROUND(#REF!+#REF!+#REF!+预安排!Q44+#REF!+'6月'!W39,5) | X39: =ROUND(#REF!+#REF!+#REF!+预安排!R44+#REF!+'6月'!X39,5) | Y39: =ROUND(#REF!+#REF!+#REF!+预安排!S44+#REF!+'6月'!Y39,5) | Z39: =ROUND(#REF!+#REF!+#REF!+预安排!#REF!+#REF!+'6月'!Z39,5) | AA39: =ROUND(#REF!+#REF!+#REF!+预安排!#REF!+#REF!+'6月'!AA39,5) | AB39: =ROUND(#REF!+#REF!+#REF!+预安排!#REF!+#REF!+'6月'!AB39,5) | AC39: T | AE39: Brand-Anonymized | AF39: 200 | AG39: =计划!O39-O39 | AH39: =ROUND(AG39/$AH$1,2)
B40: SKU-22512FF3 | C40: 是 | D40: 10 | J40: 共 | L40: 100 | M40: Product-C617F7D2 | N40: 1 | O40: =SUM(P40:AB40) | P40: =ROUND(#REF!+#REF!+#REF!+预安排!F45+#REF!+'6月'!P40,5) | Q40: =ROUND(#REF!+#REF!+#REF!+预安排!#REF!+#REF!+'6月'!Q40,5) | R40: =ROUND(#REF!+#REF!+#REF!+预安排!G45+#REF!+'6月'!R40,5) | S40: =ROUND(#REF!+#REF!+#REF!+预安排!#REF!+#REF!+'6月'!S40,5) | T40: =ROUND(#REF!+#REF!+#REF!+预安排!#REF!+#REF!+'6月'!T40,5) | U40: =ROUND(#REF!+#REF!+#REF!+预安排!O45+#REF!+'6月'!U40,5) | V40: =ROUND(#REF!+#REF!+#REF!+预安排!P45+#REF!+'6月'!V40,5) | W40: =ROUND(#REF!+#REF!+#REF!+预安排!Q45+#REF!+'6月'!W40,5) | X40: =ROUND(#REF!+#REF!+#REF!+预安排!R45+#REF!+'6月'!X40,5) | Y40: =ROUND(#REF!+#REF!+#REF!+预安排!S45+#REF!+'6月'!Y40,5) | Z40: =ROUND(#REF!+#REF!+#REF!+预安排!#REF!+#REF!+'6月'!Z40,5) | AA40: =ROUND(#REF!+#REF!+#REF!+预安排!#REF!+#REF!+'6月'!AA40,5) | AB40: =ROUND(#REF!+#REF!+#REF!+预安排!#REF!+#REF!+'6月'!AB40,5) | AC40: C | AE40: Brand-Anonymized | AF40: 200 | AG40: =计划!O40-O40 | AH40: =ROUND(AG40/$AH$1,2)
...

Sheet 计划
M1: 2025年上
A2: 工业 | B2: 代码 | C2: 重 | D2: 焦 | E2: 细 | F2: 中 | G2: 短 | H2: 爆 | I2: 创 | J2: 共 | K2: 混 | L2: 批发价 | M2: 卷烟名称 | N2: 类 | O2: 合计 | P2: 一分 | Q2: 二分 | R2: 三分 | S2: 东丽 | T2: 西青 | U2: 津南 | V2: 北辰 | W2: 滨海 | X2: 武清 | Y2: 宝坻 | Z2: 蓟州 | AA2: 静海 | AB2: 宁河 | AC2: 属 | AD2: C类 | AE2: 品牌 | AF2: 条支比
A3: 上海 | B3: SKU-C78CA26A | C3: 是 | D3: 8 | K3: 是 | L3: 100 | M3: Product-0CBDA773 | N3: 3 | O3: =SUM(P3:AB3) | P3: 37.4 | Q3: 322.5 | R3: 199.2 | S3: 68.5 | T3: 49.8 | U3: 24.9 | V3: 67.2 | W3: 74.9 | X3: 105.8 | Y3: 92.6 | Z3: 53.5 | AA3: 146.4 | AB3: 57.3 | AE3: Brand-Anonymized | AF3: 200
B4: SKU-FEFFF06B | C4: 是 | D4: 5 | K4: 是 | L4: 100 | M4: Product-2824E2BD | N4: 2 | O4: =SUM(P4:AB4) | P4: 6 | Q4: 10 | R4: 15 | S4: 30 | T4: 18 | U4: 6 | V4: 10 | W4: 6 | X4: 29 | Y4: 27 | Z4: 3 | AA4: 6 | AB4: 4 | AC4: T | AE4: Brand-Anonymized | AF4: 200
B5: SKU-2866FD1A | C5: 是 | D5: 8 | K5: 是 | L5: 100 | M5: Product-B05D24B5 | N5: 3 | O5: =SUM(P5:AB5) | P5: 10 | Q5: 20 | R5: 15 | S5: 25 | T5: 13 | U5: 1 | V5: 4 | W5: 2 | X5: 10.1 | Y5: 0 | Z5: 2 | AA5: 34.6 | AB5: 1 | AE5: Brand-Anonymized | AF5: 200
B6: SKU-0260B714 | C6: 是 | D6: 5 | K6: 是 | L6: 100 | M6: Product-9FA41960 | N6: 2 | O6: =SUM(P6:AB6) | P6: 0 | Q6: 0 | R6: 0 | S6: 0 | T6: 0 | U6: 0 | V6: 0 | W6: 0 | X6: 0 | Y6: 0 | Z6: 0 | AA6: 0 | AB6: 0 | AE6: Brand-Anonymized | AF6: 200
B7: SKU-80DD304E | C7: 是 | D7: 5 | F7: 是 | I7: 是 | K7: 是 | L7: 100 | M7: Product-104B7147 | N7: 2 | O7: =SUM(P7:AB7) | P7: 14 | Q7: 16.7 | R7: 16.4 | S7: 8 | T7: 9.8 | U7: 8 | V7: 7.8 | W7: 22.1 | X7: 13 | Y7: 9.3 | Z7: 10.2 | AA7: 8.7 | AB7: 6 | AC7: C | AD7: 标 | AE7: Brand-Anonymized | AF7: 200
B8: SKU-1DE29866 | C8: 是 | D8: 5 | F8: 是 | H8: 是 | I8: 是 | K8: 是 | L8: 100 | M8: Product-F23B59C1 | N8: 1 | O8: =SUM(P8:AB8) | P8: 29 | Q8: 34.5 | R8: 33.9 | S8: 16.5 | T8: 20.2 | U8: 16.5 | V8: 16.2 | W8: 45.7 | X8: 26.8 | Y8: 19.3 | Z8: 21 | AA8: 17.9 | AB8: 12.5 | AC8: X | AD8: 标 | AE8: Brand-Anonymized | AF8: 200
B9: 6 | M9: 北京小计 | O9: =SUM(O3:O8) | P9: 96.4 | Q9: 403.7 | R9: 279.5 | S9: 148 | T9: 110.8 | U9: 56.4 | V9: 105.2 | W9: 150.7 | X9: 184.7 | Y9: 148.2 | Z9: 89.7 | AA9: 213.6 | AB9: 80.8 | AC9: =SUM(AC3:AC8)
B10: SKU-D208A1F4 | D10: 9 | L10: 100 | M10: Product-DE70A72E | N10: 3 | O10: =SUM(P10:AB10) | P10: 469 | Q10: 457 | R10: 494 | S10: 266 | T10: 307 | U10: 304 | V10: 228 | W10: 717 | X10: 539 | Y10: 361 | Z10: 365 | AA10: 353 | AB10: 310 | AC10: T | AE10: Brand-Anonymized | AF10: 200
B11: SKU-07FCDFBC | D11: 10 | G11: 是 | I11: 是 | L11: 100 | M11: Product-7A1FEE2B | N11: 1 | O11: =SUM(P11:AB11) | P11: 0 | Q11: 0 | R11: 0 | S11: 0 | T11: 0 | U11: 0 | V11: 0 | W11: 0 | X11: 0 | Y11: 0 | Z11: 0 | AA11: 0 | AB11: 0 | AD11: 标 | AE11: Brand-Anonymized | AF11: 200
B12: SKU-F24DC4CC | D12: 10 | L12: 100 | M12: Product-3F617BC6 | N12: 1 | O12: =SUM(P12:AB12) | P12: 0 | Q12: 0 | R12: 0 | S12: 0 | T12: 0 | U12: 0 | V12: 0 | W12: 0 | X12: 0 | Y12: 0 | Z12: 0 | AA12: 0 | AB12: 0 | AD12: 方 | AE12: Brand-Anonymized | AF12: 200
B13: SKU-D943D84F | D13: 10 | L13: 100 | M13: Product-9C089579 | N13: 1 | O13: =SUM(P13:AB13) | P13: 0 | Q13: 0 | R13: 0 | S13: 0 | T13: 0 | U13: 0 | V13: 0 | W13: 0 | X13: 0 | Y13: 0 | Z13: 0 | AA13: 0 | AB13: 0 | AE13: Brand-Anonymized | AF13: 200
B14: SKU-6D9E63BD | D14: 8 | F14: 是 | I14: 是 | L14: 100 | M14: Product-BC499EF2 | N14: 1 | O14: =SUM(P14:AB14) | P14: 36.5 | Q14: 43.4 | R14: 42.6 | S14: 20.7 | T14: 25.4 | U14: 20.8 | V14: 20.3 | W14: 57.8 | X14: 33.7 | Y14: 24.2 | Z14: 26.4 | AA14: 22.5 | AB14: 15.7 | AC14: C | AD14: 方 | AE14: Brand-Anonymized | AF14: 200
B15: SKU-01FF2431 | D15: 8 | F15: 是 | I15: 是 | L15: 100 | M15: Product-C54A353F | N15: 1 | O15: =SUM(P15:AB15) | P15: 61.8 | Q15: 73.4 | R15: 72.1 | S15: 35.1 | T15: 43 | U15: 35.1 | V15: 34.4 | W15: 97.5 | X15: 57.1 | Y15: 41 | Z15: 44.7 | AA15: 38.2 | AB15: 26.6 | AC15: C | AD15: 标 | AE15: Brand-Anonymized | AF15: 200
B16: SKU-8916FAEC | D16: 8 | F16: 是 | I16: 是 | J16: 共 | L16: 100 | M16: Product-558A622A | N16: 1 | O16: =SUM(P16:AB16) | P16: 374.5 | Q16: 444.9 | R16: 436.9 | S16: 212.7 | T16: 256.9 | U16: 212.9 | V16: 208.5 | W16: 591.1 | X16: 345.8 | Y16: 248.6 | Z16: 271.2 | AA16: 231.3 | AB16: 160.9 | AC16: C | AD16: 长 | AE16: Brand-Anonymized | AF16: 200
B17: SKU-13F48E9F | D17: 8 | F17: 是 | I17: 是 | L17: 100 | M17: Product-9B1626A5 | N17: 1 | O17: =SUM(P17:AB17) | P17: 56.2 | Q17: 66.7 | R17: 65.5 | S17: 31.9 | T17: 39.1 | U17: 31.9 | V17: 31.3 | W17: 88.7 | X17: 51.9 | Y17: 37.3 | Z17: 40.7 | AA17: 34.7 | AB17: 24.1 | AC17: C | AD17: 长 | AE17: Brand-Anonymized | AF17: 200
B18: SKU-84735B62 | C18: 是 | D18: 10 | L18: 100 | M18: Product-61AE19F7 | N18: 3 | O18: =SUM(P18:AB18) | P18: 2176 | Q18: 2428 | R18: 2624 | S18: 1122 | T18: 905 | U18: 830 | V18: 760 | W18: 2782 | X18: 680 | Y18: 826 | Z18: 1009 | AA18: 564 | AB18: 674 | AC18: T | AE18: Brand-Anonymized | AF18: 200
B19: SKU-9356910A | C19: 是 | D19: 11 | L19: 100 | M19: Product-1433AC24 | N19: 2 | O19: =SUM(P19:AB19) | P19: 337 | Q19: 316 | R19: 316 | S19: 148 | T19: 139 | U19: 97 | V19: 112 | W19: 272 | X19: 43 | Y19: 15 | Z19: 119 | AA19: 20 | AB19: 66 | AC19: T | AE19: Brand-Anonymized | AF19: 200
B20: SKU-A1C9F3C5 | C20: 是 | D20: 10 | J20: 共 | L20: 100 | M20: Product-A7F669A5 | N20: 2 | O20: =SUM(P20:AB20) | P20: 314 | Q20: 328 | R20: 383 | S20: 58 | T20: 161 | U20: 68 | V20: 403 | W20: 704 | X20: 27 | Y20: 86 | Z20: 124 | AA20: 133 | AB20: 131 | AC20: T | AE20: Brand-Anonymized | AF20: 200
B21: SKU-9FED3CD7 | C21: 是 | D21: 6 | E21: 是 | I21: 是 | L21: 100 | M21: Product-80F515FA | N21: 1 | O21: =SUM(P21:AB21) | P21: 0 | Q21: 0 | R21: 0 | S21: 0 | T21: 0 | U21: 0 | V21: 0 | W21: 0 | X21: 0 | Y21: 0 | Z21: 0 | AA21: 0 | AB21: 0 | AD21: 方 | AE21: Brand-Anonymized | AF21: 200
B22: SKU-D2D4FD85 | C22: 是 | D22: 8 | E22: 是 | I22: 是 | L22: 100 | M22: Product-D1D130D9 | N22: 1 | O22: =SUM(P22:AB22) | P22: 0 | Q22: 0 | R22: 0 | S22: 0 | T22: 0 | U22: 0 | V22: 0 | W22: 0 | X22: 0 | Y22: 0 | Z22: 0 | AA22: 0 | AB22: 0 | AE22: Brand-Anonymized | AF22: 200
B23: SKU-2324D87D | C23: 是 | D23: 9 | F23: 是 | I23: 是 | L23: 100 | M23: Product-142947AA | N23: 1 | O23: =SUM(P23:AB23) | P23: 19.2 | Q23: 22.8 | R23: 22.4 | S23: 10.9 | T23: 13.4 | U23: 10.9 | V23: 10.7 | W23: 30.3 | X23: 17.7 | Y23: 12.7 | Z23: 13.9 | AA23: 11.9 | AB23: 8.2 | AC23: C | AD23: 长 | AE23: Brand-Anonymized | AF23: 200
B24: SKU-D3A8D0D1 | C24: 是 | D24: 9 | F24: 是 | I24: 是 | L24: 100 | M24: Product-B80128BB | N24: 1 | O24: =SUM(P24:AB24) | P24: 21.6 | Q24: 25.6 | R24: 25.2 | S24: 12.3 | T24: 15 | U24: 12.3 | V24: 12 | W24: 33.7 | X24: 19.9 | Y24: 14.3 | Z24: 15.6 | AA24: 13.3 | AB24: 9.2 | AC24: X | AD24: 长 | AE24: Brand-Anonymized | AF24: 200
B25: SKU-55B49425 | C25: 是 | D25: 11 | J25: 共 | L25: 100 | M25: Product-2E005B6F | N25: 1 | O25: =SUM(P25:AB25) | P25: 800 | Q25: 1024 | R25: 1005 | S25: 480 | T25: 588 | U25: 451 | V25: 471 | W25: 1276 | X25: 750 | Y25: 561 | Z25: 565 | AA25: 522 | AB25: 298 | AC25: T | AE25: Brand-Anonymized | AF25: 200
B26: SKU-7E7C0C23 | C26: 是 | D26: 11 | J26: 共 | L26: 100 | M26: Product-8C5BA899 | N26: 1 | O26: =SUM(P26:AB26) | P26: 287.4 | Q26: 362.8 | R26: 334.8 | S26: 160.3 | T26: 196.3 | U26: 160.3 | V26: 156.5 | W26: 453.4 | X26: 259.9 | Y26: 186.8 | Z26: 203.9 | AA26: 173.6 | AB26: 100 | AC26: T | AE26: Brand-Anonymized | AF26: 200
B27: SKU-581048FF | C27: 是 | D27: 11 | L27: 100 | M27: Product-9C9F0DD0 | N27: 1 | O27: =SUM(P27:AB27) | P27: 14.4 | Q27: 17 | R27: 16.7 | S27: 8.2 | T27: 10 | U27: 8.2 | V27: 7.9 | W27: 22.4 | X27: 13.2 | Y27: 9.5 | Z27: 10.4 | AA27: 8.9 | AB27: 6.2 | AC27: C | AD27: 方 | AE27: Brand-Anonymized | AF27: 200
B28: SKU-1943C75B | C28: 是 | D28: 10 | F28: 是 | I28: 是 | J28: 共 | L28: 100 | M28: Product-62BC29B7 | N28: 1 | O28: =SUM(P28:AB28) | P28: 31.5 | Q28: 37.4 | R28: 36.7 | S28: 17.9 | T28: 21.9 | U28: 17.9 | V28: 17.5 | W28: 49.6 | X28: 29 | Y28: 20.9 | Z28: 22.8 | AA28: 19.4 | AB28: 13.5 | AC28: C | AD28: 方 | AE28: Brand-Anonymized | AF28: 200
B29: SKU-51C641E5 | C29: 是 | D29: 10 | F29: 是 | I29: 是 | J29: 共 | L29: 100 | M29: Product-4CA63C06 | N29: 1 | O29: =SUM(P29:AB29) | P29: 264.5 | Q29: 315.1 | R29: 308.6 | S29: 150.6 | T29: 184.6 | U29: 150.6 | V29: 147.9 | W29: 418.1 | X29: 244.3 | Y29: 175.4 | Z29: 192 | AA29: 163.5 | AB29: 114.8 | AC29: T | AD29: 长 | AE29: Brand-Anonymized | AF29: 200
B30: SKU-740A9334 | C30: 是 | D30: 10 | G30: 是 | I30: 是 | L30: 100 | M30: Product-7726A962 | N30: 1 | O30: =SUM(P30:AB30) | P30: 0 | Q30: 0 | R30: 0 | S30: 0 | T30: 0 | U30: 0 | V30: 0 | W30: 0 | X30: 0 | Y30: 0 | Z30: 0 | AA30: 0 | AB30: 0 | AD30: 方 | AE30: Brand-Anonymized | AF30: 200
B31: SKU-ABAD8823 | C31: 是 | D31: 8 | E31: 是 | I31: 是 | J31: 共 | L31: 100 | M31: Product-342D1F0D | N31: 1 | O31: =SUM(P31:AB31) | P31: 40.7 | Q31: 48.4 | R31: 47.5 | S31: 23.2 | T31: 28.4 | U31: 23.2 | V31: 22.7 | W31: 64.1 | X31: 37.6 | Y31: 27.1 | Z31: 29.5 | AA31: 25.1 | AB31: 17.5 | AC31: C | AD31: 细 | AE31: Brand-Anonymized | AF31: 200
B32: SKU-CD40403A | C32: 是 | D32: 8 | E32: 是 | I32: 是 | J32: 共 | L32: 100 | M32: Product-D6D3CCE6 | N32: 1 | O32: =SUM(P32:AB32) | P32: 3 | Q32: 4.4 | R32: 2.4 | S32: 2.1 | T32: 2.6 | U32: 2.1 | V32: 2.1 | W32: 6 | X32: 3.5 | Y32: 2.5 | Z32: 2.7 | AA32: 2.3 | AB32: 1.6 | AC32: C | AD32: 标 | AE32: Brand-Anonymized | AF32: 200
B33: SKU-B0D292B1 | C33: 是 | D33: 10 | G33: 是 | I33: 是 | L33: 100 | M33: Product-7726A962 | N33: 1 | O33: =SUM(P33:AB33) | P33: 1.2 | Q33: 1.4 | R33: 1.4 | S33: 0.7 | T33: 0.8 | U33: 0.7 | V33: 0.7 | W33: 2 | X33: 1.1 | Y33: 0.8 | Z33: 0.9 | AA33: 0.8 | AB33: 0.5 | AC33: X | AD33: 标 | AE33: Brand-Anonymized | AF33: 200
B34: SKU-D5FB4C4D | D34: 10 | L34: 100 | M34: Product-3DCEC0C0 | N34: 1 | O34: =SUM(P34:AB34) | P34: 0 | Q34: 0 | R34: 0 | S34: 0 | T34: 0 | U34: 0 | V34: 0 | W34: 0 | X34: 0 | Y34: 0 | Z34: 0 | AA34: 0 | AB34: 0 | AD34: 标 | AE34: Brand-Anonymized | AF34: 200
B35: SKU-DCF98B33 | D35: 10 | L35: 100 | M35: Product-3DCEC0C0 | N35: 1 | O35: =SUM(P35:AB35) | P35: 2.7 | Q35: 3.2 | R35: 3.2 | S35: 1.5 | T35: 1.9 | U35: 1.5 | V35: 1.5 | W35: 4.3 | X35: 2.5 | Y35: 1.8 | Z35: 2 | AA35: 1.7 | AB35: 1.2 | AC35: X | AD35: 标 | AE35: Brand-Anonymized | AF35: 200
